Workbook

Sheet TOTAL
M1: Horas Normais | N1: PROV.: 420 - DSR | O1: AD. Noturno | P1: Periculosidade | Q1: SOMAR COM A PERICULOSIDADE!!!! | R1: UNIFCADO Reembolso Desc. Indev. | S1: UNIFCADO Reembolso Desc. Indev. | T1: Aux. Educação | U1: PROV.: 159 - Dissidio Retroativo | W1: juntar com SALÁRIO BASE!!! | Y1: Gratificação | Z1: Sobre Aviso | AA1: Adicional de transferência | AB1: PROV.: 296 - Adic. de Transferência/Aux. Viagem | AC1: Comissão | AD1: HE 50% | AE1: HE 100% | AF1: Reflexo DSR HE | AG1: Reembolso Desc. Indev. | AH1: PROV:. 433 - DEV DESCONTO INDEVIDO | AI1: PROV.: 420 - DSR | AJ1: Salário Familia | AK1: PROV:. 433 - DEV DESCONTO INDEVIDO | AL1: Insuficiencia de saldo | AM1: Arredondamento | AO1: Falta + DSR | AP1: VA | AQ1: VT | AR1: Adiantamento | AS1: Insuficiencia de Saldo | AT1: Arredondamento | AU1: 2 via de VT | AV1: Plano Odontologico | AW1: Plano Odontologico | AY1: Contribuição sindical | AZ1: UNIFICADO COM 398 - FALTA + DSR | BA1: Multa de Transito | BB1: Plano de Saúde descontado na folha | BC1: Plano de Saúde descontado na folha | BD1: Plano de Saúde descontado na folha | BE1: EXTRA | BF1: Emprestimo (cred trab) | BG1: INSS | BH1: IRRF | BI1: Pensão Alimenticia | BJ1: Pensão Alimenticia 2 | BK1: DESC.: 609 - Insuficiência de Saldo | CH1: Plano de Saúde TOTAL (Titular+dependentes+cop.) | CM1: Odontológico TOTAL (titular+dependentes)
K2: Locação/Sal. Contratual | AA2: UNIFICADO COM AUXILIO VIAGEM | AB2: UNIFICADO COM AD TRANSFERENCIA | AG2: 433 e 456 UNIFICADOS!! | AH2: 433 e 456 UNIFICADOS!! | AI2: UNIFICADO COM DSR!!! | AS2: DUPLICADO | AV2: UNIFICADO AP+AQ | AW2: UNIFICADO AP+AQ | AZ2: UNIFICADO COM 398 - FALTA + DSR | BB2: UNIFICADO COM 699 - AU+AV+AW | BI2: UNFICADO EM 920 - BB+BC | BJ2: UNFICADO EM 920 - BB+BC | CD2: CUSTO EMPRESA - VALORES DEPOSITADOS
A3: NOME/SÓLIDES | B3: DATA DEMISSÃO | C3: CONFERIR | D3: R$ Total Custos | E3: Referência | F3: CNPJ | G3: Matrícula | H3: Colaborador | I3: Função | J3: Admissão | K3: Sal. Contratual | L3: Observações | M3: PROV.: 001 - Salário Base | N3: PROV.: 014 - Férias Períodos Quebrados ou Cheios | O3: PROV.: 017 - Noturno 20% | P3: PROV.: 020 - Periculosidade 30% | Q3: PROV.: 026 - Insalubridade 20% | R3: PROV.: 027 - Dif. Férias | S3: PROV.: 069 - Diferença de salario | T3: PROV.: 155 - Auxílio Creche/Educaçao | U3: PROV.: 159 - Dissidio Retroativo 1/3 | V3: PROV:. 183- Acumulo de Função | W3: PROV.: 200 - Salário Maternidade | X3: PROV:. 231 - Devolução Ass Odontológica | Y3: PROV.: 245 - Prêmio | Z3: PROV.: 259 - Adicional de Horas Sobre Aviso | AA3: PROV.: 296 - Adicional de Transferencia | AB3: PROV.: 313 - Auxilio viagem 25% | AC3: PROV.: 400 - Comissão | AD3: PROV.: 401 - Hora Extra 50% | AE3: PROV.: 402 - Hora Extra 100% | AF3: PROV.: 420 - Repouso Remunerado | AG3: PROV:. 433 - DEV DESCONTO INDEVIDO VT | AH3: PROV.: 456 - Estorno de Provisão (Crédito Trabalhado) | AI3: PROV.: 461 - DSR Sobre Comissões | AJ3: PROV.: 599 - Salário Família | AK3: PROV.: 647 - DEVOLUÇÃO PLANO | AL3: PROV.: 998 - Insuficiência de Saldo | AM3: PROV.: 999 - Arredondamento | AN3: R$ Proventos | AO3: DESC.: 398 - Faltas em Dias | AP3: DESC.: 600 - Alimentação | AQ3: DESC.: 604 - Vale Transporte | AR3: DESC.: 606 - Adiantamento viagem | AS3: DESC.: 609 - Insuficiência de Saldo | AT3: DESC.: 610 - Arredondamento | AU3: DESC.: 616 - Rio Card | AV3: DESC.: 623 - Assistência Odontológica - Part. | AW3: DESC.: 623 - Assistência Odontológica - Part. Dep. | AX3: DESC.: 636 - Aux. Viagem | AY3: DESC.: 645 - Contribuicao Assistencial | AZ3: DESC.: 674 - Desconto Repouso Remunerado | BA3: DESC.: 681 - Desconto multa de transito | BB3: DESC.: 698 - Outras Despesas Co-participação - Part. | BC3: DESC.: 699 - Plano De Saúde Part. | BD3: DESC.: 699 - Plano De Saúde - Part. Dep. | BE3: DESC.: 701 - 13° Pago Durante o Ano (Desconto) | BF3: DESC.: 711 - Empréstimo (Crédito Trabalhador) Parc. | BG3: DESC.: 903 - INSS Folha | BH3: DESC.: 914 - IRRF Folha | BI3: DESC.: 920 - Pensao Alimenticia | BJ3: DESC.: 997 - Pensão | BK3: DESC.: 998 - Insuficiência de Saldo | BL3: R$ Descontos | BM3: R$ Líquido | BN3: Parcela 13º salário | BO3: Parcela de Férias | BP3: 1/3 de Férias | BQ3: INSS Empresa | BR3: FGTS | BS3: Rest. Alimentação | BT3: Rest. Transporte | BU3: Rest. Plano de Saúde TOTAL | BV3: SEGURO DE VIDA | BW3: TREINAMENTOS | BX3: EXAMES | BY3: R$ Empresa | CA3: Nome | CB3: Rest. Plano de saúde | CC3: Rest. Plano Odonto | CD3: ALIMENTAÇÃO | CE3: TRANSPORTE | CF3: PLANO DE SAÚDE | CG3: PLANO ODONTO | CH3: DESC.: 699 - Plano De Saúde | CI3: DESC.: 920 - Pensao Alimenticia | CJ3: PROV.: 296 - Adic. de Transferência/Aux. Viagem | CK3: PROV.: 461 - DSR Sobre Comissões | CL3: PROV:. 433 - DEV DESCONTO INDEVIDO | CM3: DESC.: 623 - Assistência Odontológica | CN3: Total Proventos (R$) | CO3: Total Descontos (R$) | CP3: Valor Líquido (R$) | CQ3: Base INSS (R$) | CR3: Alíquota INSS () | CS3: Base FGTS (R$) | CT3: Valor FGTS (R$) | CU3: Base IRRF (R$)
A4: =IFERROR(__xludf.DUMMYFUNCTION("unique(flatten(LISTAFOLHAS!A3:A1001))"),"ADRIANO SOUZA SANTOS") -> ADRIANO SOUZA SANTOS | C4: =IF(COUNTIF(A:A, H4)>0, "OK", "Incompleto") -> OK | D4: =AN4+BY4 -> 5074.1297 | E4: 45809 | F4: 07.391.921/0001-71 | G4: 136 | H4: ADRIANO SOUZA SANTOS | I4: TECNICO DE TELECOMUNI | J4: 41992 | K4: 3159.37 | M4: 3159.37 | O4: 0 | P4: 0 | W4: 0 | AB4: 0 | AD4: 0 | AE4: 0 | AF4: 0 | AM4: 0.44 | AN4: =SUM(M4:AM4) -> 3159.81 | AQ4: -189.56 | AT4: -0.18 | AV4: -14 | AW4: -42 | BB4: 0 | BC4: -34.55 | BD4: 0 | BG4: -272.52 | BH4: 0 | BI4: 0 | BL4: =SUM(AO4:BK4) -> -552.81 | BM4: =AN4+BL4 -> 2607 | BN4: =K4/12*1 -> 263.28083 | BO4: =K4/12*1 -> 263.28083 | BP4: =BO4/3 -> 87.760278 | BQ4: =CQ4*CR4% -> 272.51778 | BR4: =CT4 -> 252.74 | BS4: =-(-CD4-AP4) -> 560 | BT4: =IF(CE4+AQ4<0, 0, CE4+AQ4) -> 49.84 | BU4: =CB4+CC4 -> 151.19 | BV4: =SUMIFS('SEGURO DE VIDA'!E:E, 'SEGURO DE VIDA'!D:D, H4, 'SEGURO DE VIDA'!G:G, E4) -> 13.71 | BW4: =SUMIFS(TREINAMENTOS!E:E, TREINAMENTOS!D:D, H4, TREINAMENTOS!G:G, E4) -> 0 | BX4: =SUMIFS(EXAMES!E:E, EXAMES!D:D, H4, EXAMES!G:G, E4) -> 0 | BY4: =SUM(BN4:BU4)+SUM(BV4:BX4) -> 1914.3197 | CA4: ADRIANO SOUZA SANTOS | CB4: =IF(SUM(BB4:BD4)+CF4<0, 0, SUM(BB4:BD4)+CF4) -> 151.19 | CC4: =IF(SUM(AV4:AW4)+CG4<0, 0, SUM(AV4:AW4)+CG4) -> 0 | CD4: =SUMIFS(ALIMENTAÇÃO!E:E, ALIMENTAÇÃO!D:D, H4, ALIMENTAÇÃO!G:G, E4) -> 560 | CE4: =SUMIFS(TRANSPORTE!E:E, TRANSPORTE!D:D, H4, TRANSPORTE!G:G, E4) -> 239.4 | CF4: =SUMIFS('PLANO DE SAÚDE'!E:E, 'PLANO DE SAÚDE'!D:D, H4, 'PLANO DE SAÚDE'!G:G, E4) -> 185.74 | CG4: =SUMIFS('PLANO ODONTO'!E:E, 'PLANO ODONTO'!D:D, H4, 'PLANO ODONTO'!G:G, E4) -> 56 | CH4: =BB4+BC4+BD4 -> -34.55 | CI4: =BI4+BJ4 -> 0 | CJ4: =AA4+AB4 -> 0 | CM4: =AV4+AW4 -> -56 | CN4: 3159.81 | CO4: -552.81 | CP4: 2607 | CQ4: 3159.37 | CR4: 8.6257 | CS4: 3159.37 | CT4: 252.74 | CU4: 2552.17
A5: =IFERROR(__xludf.DUMMYFUNCTION("""COMPUTED_VALUE"""),"ALESSANDRO SOARES RIBEIRO") -> ALESSANDRO SOARES RIBEIRO | C5: =IF(COUNTIF(A:A, H5)>0, "OK", "Incompleto") -> OK | D5: =AN5+BY5 -> 3618.1086 | E5: 45809 | F5: 07.391.921/0001-71 | G5: 3467 | H5: ALESSANDRO SOARES RIBEIRO | I5: MOTORISTA DE CARRO DE | J5: 45551 | K5: 1800 | M5: 1800 | O5: 0 | P5: 0 | W5: 0 | AB5: 0 | AD5: 279 | AE5: 0 | AF5: 69.75 | AM5: 0.88 | AN5: =SUM(M5:AM5) -> 2149.63 | AQ5: 0 | AT5: -0.78 | AV5: -14 | AW5: 0 | BB5: 0 | BC5: -2.24 | BD5: 0 | BG5: -170.61 | BH5: 0 | BI5: 0 | BL5: =SUM(AO5:BK5) -> -187.63 | BM5: =AN5+BL5 -> 1962 | BN5: =K5/12*1 -> 150 | BO5: =K5/12*1 -> 150 | BP5: =BO5/3 -> 50 | BQ5: =CQ5*CR5% -> 170.6086 | BR5: =CT5 -> 171.9 | BS5: =-(-CD5-AP5) -> 630 | BT5: =IF(CE5+AQ5<0, 0, CE5+AQ5) -> 0 | BU5: =CB5+CC5 -> 132.26 | BV5: =SUMIFS('SEGURO DE VIDA'!E:E, 'SEGURO DE VIDA'!D:D, H5, 'SEGURO DE VIDA'!G:G, E5) -> 13.71 | BW5: =SUMIFS(TREINAMENTOS!E:E, TREINAMENTOS!D:D, H5, TREINAMENTOS!G:G, E5) -> 0 | BX5: =SUMIFS(EXAMES!E:E, EXAMES!D:D, H5, EXAMES!G:G, E5) -> 0 | BY5: =SUM(BN5:BU5)+SUM(BV5:BX5) -> 1468.4786 | CA5: ALESSANDRO SOARES RIBEIRO | CB5: =IF(SUM(BB5:BD5)+CF5<0, 0, SUM(BB5:BD5)+CF5) -> 132.26 | CC5: =IF(SUM(AV5:AW5)+CG5<0, 0, SUM(AV5:AW5)+CG5) -> 0 | CD5: =SUMIFS(ALIMENTAÇÃO!E:E, ALIMENTAÇÃO!D:D, H5, ALIMENTAÇÃO!G:G, E5) -> 630 | CE5: =SUMIFS(TRANSPORTE!E:E, TRANSPORTE!D:D, H5, TRANSPORTE!G:G, E5) -> 0 | CF5: =SUMIFS('PLANO DE SAÚDE'!E:E, 'PLANO DE SAÚDE'!D:D, H5, 'PLANO DE SAÚDE'!G:G, E5) -> 134.5 | CG5: =SUMIFS('PLANO ODONTO'!E:E, 'PLANO ODONTO'!D:D, H5, 'PLANO ODONTO'!G:G, E5) -> 14 | CH5: =BB5+BC5+BD5 -> -2.24 | CI5: =BI5+BJ5 -> 0 | CJ5: =AA5+AB5 -> 0 | CM5: =AV5+AW5 -> -14 | CN5: 2149.63 | CO5: -187.63 | CP5: 1962 | CQ5: 2148.75 | CR5: 7.9399 | CS5: 2148.75 | CT5: 171.9 | CU5: 1541.55
A6: =IFERROR(__xludf.DUMMYFUNCTION("""COMPUTED_VALUE"""),"ALEXANDRE FERREIRA DE LIMA") -> ALEXANDRE FERREIRA DE LIMA | C6: =IF(COUNTIF(A:A, H6)>0, "OK", "Incompleto") -> OK | D6: =AN6+BY6 -> 3787.5095 | E6: 45809 | F6: 07.391.921/0001-71 | G6: 3465 | H6: ALEX ANTONIO VICTORINO | I6: INSTALADOR JUNIOR | J6: 45537 | K6: 1600 | M6: 1600 | O6: 0 | P6: 480 | W6: 0 | AB6: 0 | AD6: 123.24 | AE6: 0 | AF6: 30.81 | AM6: 0.74 | AN6: =SUM(M6:AM6) -> 2234.79 | AQ6: -96 | AT6: -0.95 | AV6: 0 | AW6: 0 | BB6: 0 | BC6: -34.55 | BD6: 0 | BG6: -178.29 | BH6: 0 | BI6: 0 | BL6: =SUM(AO6:BK6) -> -309.79 | BM6: =AN6+BL6 -> 1925 | BN6: =K6/12*1 -> 133.33333 | BO6: =K6/12*1 -> 133.33333 | BP6: =BO6/3 -> 44.444444 | BQ6: =CQ6*CR6% -> 178.28836 | BR6: =CT6 -> 178.72 | BS6: =-(-CD6-AP6) -> 525 | BT6: =IF(CE6+AQ6<0, 0, CE6+AQ6) -> 194.7 | BU6: =CB6+CC6 -> 151.19 | BV6: =SUMIFS('SEGURO DE VIDA'!E:E, 'SEGURO DE VIDA'!D:D, H6, 'SEGURO DE VIDA'!G:G, E6) -> 13.71 | BW6: =SUMIFS(TREINAMENTOS!E:E, TREINAMENTOS!D:D, H6, TREINAMENTOS!G:G, E6) -> 0 | BX6: =SUMIFS(EXAMES!E:E, EXAMES!D:D, H6, EXAMES!G:G, E6) -> 0 | BY6: =SUM(BN6:BU6)+SUM(BV6:BX6) -> 1552.7195 | CA6: ALEX ANTONIO VICTORINO | CB6: =IF(SUM(BB6:BD6)+CF6<0, 0, SUM(BB6:BD6)+CF6) -> 151.19 | CC6: =IF(SUM(AV6:AW6)+CG6<0, 0, SUM(AV6:AW6)+CG6) -> 0 | CD6: =SUMIFS(ALIMENTAÇÃO!E:E, ALIMENTAÇÃO!D:D, H6, ALIMENTAÇÃO!G:G, E6) -> 525 | CE6: =SUMIFS(TRANSPORTE!E:E, TRANSPORTE!D:D, H6, TRANSPORTE!G:G, E6) -> 290.7 | CF6: =SUMIFS('PLANO DE SAÚDE'!E:E, 'PLANO DE SAÚDE'!D:D, H6, 'PLANO DE SAÚDE'!G:G, E6) -> 185.74 | CG6: =SUMIFS('PLANO ODONTO'!E:E, 'PLANO ODONTO'!D:D, H6, 'PLANO ODONTO'!G:G, E6) -> 0 | CH6: =BB6+BC6+BD6 -> -34.55 | CI6: =BI6+BJ6 -> 0 | CJ6: =AA6+AB6 -> 0 | CM6: =AV6+AW6 -> 0 | CN6: 2234.79 | CO6: -309.79 | CP6: 1925 | CQ6: 2234.05 | CR6: 7.9805 | CS6: 2234.05 | CT6: 178.72 | CU6: 1626.85
A7: =IFERROR(__xludf.DUMMYFUNCTION("""COMPUTED_VALUE"""),"ALEXANDRE SOUZA DE ABREU") -> ALEXANDRE SOUZA DE ABREU | C7: =IF(COUNTIF(A:A, H7)>0, "OK", "Incompleto") -> OK | D7: =AN7+BY7 -> 4931.367 | E7: 45809 | F7: 07.391.921/0001-71 | G7: 3373 | H7: ALEX SENA DE SOUZA | I7: TECNICO EM FIBRA OPTICA | J7: 45065 | K7: 2776.98 | M7: 2776.98 | O7: 0 | P7: 0 | W7: 0 | AB7: 0 | AD7: 0 | AE7: 0 | AF7: 0 | AM7: 0.96 | AN7: =SUM(M7:AM7) -> 2777.94 | AQ7: -166.62 | AT7: -0.56 | AV7: -14 | AW7: 0 | BB7: 0 | BC7: -94.61 | BD7: 0 | BG7: -227.15 | BH7: 0 | BI7: 0 | BL7: =SUM(AO7:BK7) -> -502.94 | BM7: =AN7+BL7 -> 2275 | BN7: =K7/12*1 -> 231.415 | BO7: =K7/12*1 -> 231.415 | BP7: =BO7/3 -> 77.138333 | BQ7: =CQ7*CR7% -> 227.14863 | BR7: =CT7 -> 222.15 | BS7: =-(-CD7-AP7) -> 665 | BT7: =IF(CE7+AQ7<0, 0, CE7+AQ7) -> 158.28 | BU7: =CB7+CC7 -> 127.17 | BV7: =SUMIFS('SEGURO DE VIDA'!E:E, 'SEGURO DE VIDA'!D:D, H7, 'SEGURO DE VIDA'!G:G, E7) -> 13.71 | BW7: =SUMIFS(TREINAMENTOS!E:E, TREINAMENTOS!D:D, H7, TREINAMENTOS!G:G, E7) -> 200 | BX7: =SUMIFS(EXAMES!E:E, EXAMES!D:D, H7, EXAMES!G:G, E7) -> 0 | BY7: =SUM(BN7:BU7)+SUM(BV7:BX7) -> 2153.427 | CA7: ALEX SENA DE SOUZA | CB7: =IF(SUM(BB7:BD7)+CF7<0, 0, SUM(BB7:BD7)+CF7) -> 127.17 | CC7: =IF(SUM(AV7:AW7)+CG7<0, 0, SUM(AV7:AW7)+CG7) -> 0 | CD7: =SUMIFS(ALIMENTAÇÃO!E:E, ALIMENTAÇÃO!D:D, H7, ALIMENTAÇÃO!G:G, E7) -> 665 | CE7: =SUMIFS(TRANSPORTE!E:E, TRANSPORTE!D:D, H7, TRANSPORTE!G:G, E7) -> 324.9 | CF7: =SUMIFS('PLANO DE SAÚDE'!E:E, 'PLANO DE SAÚDE'!D:D, H7, 'PLANO DE SAÚDE'!G:G, E7) -> 221.78 | CG7: =SUMIFS('PLANO ODONTO'!E:E, 'PLANO ODONTO'!D:D, H7, 'PLANO ODONTO'!G:G, E7) -> 14 | CH7: =BB7+BC7+BD7 -> -94.61 | CI7: =BI7+BJ7 -> 0 | CJ7: =AA7+AB7 -> 0 | CM7: =AV7+AW7 -> -14 | CN7: 2777.94 | CO7: -502.94 | CP7: 2275 | CQ7: 2776.98 | CR7: 8.1797 | CS7: 2776.98 | CT7: 222.15 | CU7: 2169.78
A8: =IFERROR(__xludf.DUMMYFUNCTION("""COMPUTED_VALUE"""),"ALEX ANTONIO VICTORINO") -> ALEX ANTONIO VICTORINO | C8: =IF(COUNTIF(A:A, H8)>0, "OK", "Incompleto") -> OK | D8: =AN8+BY8 -> 4164.0681 | E8: 45809 | F8: 07.391.921/0001-71 | G8: 3515 | H8: ALEXANDRE FERREIRA DE LIMA | I8: ELETRICISTA | J8: 45726 | K8: 2000 | M8: 2000 | O8: 0 | P8: 600 | W8: 0 | AB8: 0 | AD8: 0 | AE8: 0 | AF8: 0 | AM8: 0.43 | AN8: =SUM(M8:AM8) -> 2600.43 | AQ8: 0 | AT8: -0.7 | AV8: -14 | AW8: -14 | BB8: 0 | BC8: -94.61 | BD8: -125.89 | BG8: -211.23 | BH8: 0 | BI8: 0 | BL8: =SUM(AO8:BK8) -> -460.43 | BM8: =AN8+BL8 -> 2140 | BN8: =K8/12*1 -> 166.66667 | BO8: =K8/12*1 -> 166.66667 | BP8: =BO8/3 -> 55.555556 | BQ8: =CQ8*CR8% -> 211.2292 | BR8: =CT8 -> 208 | BS8: =-(-CD8-AP8) -> 665 | BT8: =IF(CE8+AQ8<0, 0, CE8+AQ8) -> 0 | BU8: =CB8+CC8 -> 76.81 | BV8: =SUMIFS('SEGURO DE VIDA'!E:E, 'SEGURO DE VIDA'!D:D, H8, 'SEGURO DE VIDA'!G:G, E8) -> 13.71 | BW8: =SUMIFS(TREINAMENTOS!E:E, TREINAMENTOS!D:D, H8, TREINAMENTOS!G:G, E8) -> 0 | BX8: =SUMIFS(EXAMES!E:E, EXAMES!D:D, H8, EXAMES!G:G, E8) -> 0 | BY8: =SUM(BN8:BU8)+SUM(BV8:BX8) -> 1563.6381 | CA8: ALEXANDRE FERREIRA DE LIMA | CB8: =IF(SUM(BB8:BD8)+CF8<0, 0, SUM(BB8:BD8)+CF8) -> 76.81 | CC8: =IF(SUM(AV8:AW8)+CG8<0, 0, SUM(AV8:AW8)+CG8) -> 0 | CD8: =SUMIFS(ALIMENTAÇÃO!E:E, ALIMENTAÇÃO!D:D, H8, ALIMENTAÇÃO!G:G, E8) -> 665 | CE8: =SUMIFS(TRANSPORTE!E:E, TRANSPORTE!D:D, H8, TRANSPORTE!G:G, E8) -> 0 | CF8: =SUMIFS('PLANO DE SAÚDE'!E:E, 'PLANO DE SAÚDE'!D:D, H8, 'PLANO DE SAÚDE'!G:G, E8) -> 297.31 | CG8: =SUMIFS('PLANO ODONTO'!E:E, 'PLANO ODONTO'!D:D, H8, 'PLANO ODONTO'!G:G, E8) -> 28 | CH8: =BB8+BC8+BD8 -> -220.5 | CI8: =BI8+BJ8 -> 0 | CJ8: =AA8+AB8 -> 0 | CM8: =AV8+AW8 -> -28 | CN8: 2600.43 | CO8: -460.43 | CP8: 2140 | CQ8: 2600 | CR8: 8.1242 | CS8: 2600 | CT8: 208 | CU8: 1992.8
A9: =IFERROR(__xludf.DUMMYFUNCTION("""COMPUTED_VALUE"""),"ALEX SENA DE SOUZA") -> ALEX SENA DE SOUZA | C9: =IF(COUNTIF(A:A, H9)>0, "OK", "Incompleto") -> OK | D9: =AN9+BY9 -> 4308.0105 | E9: 45809 | F9: 07.391.921/0001-71 | G9: 187 | H9: ALEXANDRE SOUZA DE ABREU | I9: INST REDES TELEMATICAS | J9: 42248 | K9: 2495.63 | M9: 2495.63 | O9: 0 | P9: 0 | W9: 0 | AB9: 0 | AD9: 0 | AE9: 0 | AF9: 0 | AM9: 0.86 | AN9: =SUM(M9:AM9) -> 2496.49 | AQ9: -149.74 | AT9: -0.23 | AV9: -14 | AW9: 0 | BB9: -21.45 | BC9: -34.55 | BD9: -200.69 | BG9: -201.83 | BH9: 0 | BI9: 0 | BL9: =SUM(AO9:BK9) -> -622.49 | BM9: =AN9+BL9 -> 1874 | BN9: =K9/12*1 -> 207.96917 | BO9: =K9/12*1 -> 207.96917 | BP9: =BO9/3 -> 69.323056 | BQ9: =CQ9*CR9% -> 201.82908 | BR9: =CT9 -> 199.65 | BS9: =-(-CD9-AP9) -> 665 | BT9: =IF(CE9+AQ9<0, 0, CE9+AQ9) -> 175.16 | BU9: =CB9+CC9 -> 70.91 | BV9: =SUMIFS('SEGURO DE VIDA'!E:E, 'SEGURO DE VIDA'!D:D, H9, 'SEGURO DE VIDA'!G:G, E9) -> 13.71 | BW9: =SUMIFS(TREINAMENTOS!E:E, TREINAMENTOS!D:D, H9, TREINAMENTOS!G:G, E9) -> 0 | BX9: =SUMIFS(EXAMES!E:E, EXAMES!D:D, H9, EXAMES!G:G, E9) -> 0 | BY9: =SUM(BN9:BU9)+SUM(BV9:BX9) -> 1811.5205 | CA9: ALEXANDRE SOUZA DE ABREU | CB9: =IF(SUM(BB9:BD9)+CF9<0, 0, SUM(BB9:BD9)+CF9) -> 70.91 | CC9: =IF(SUM(AV9:AW9)+CG9<0, 0, SUM(AV9:AW9)+CG9) -> 0 | CD9: =SUMIFS(ALIMENTAÇÃO!E:E, ALIMENTAÇÃO!D:D, H9, ALIMENTAÇÃO!G:G, E9) -> 665 | CE9: =SUMIFS(TRANSPORTE!E:E, TRANSPORTE!D:D, H9, TRANSPORTE!G:G, E9) -> 324.9 | CF9: =SUMIFS('PLANO DE SAÚDE'!E:E, 'PLANO DE SAÚDE'!D:D, H9, 'PLANO DE SAÚDE'!G:G, E9) -> 327.6 | CG9: =SUMIFS('PLANO ODONTO'!E:E, 'PLANO ODONTO'!D:D, H9, 'PLANO ODONTO'!G:G, E9) -> 14 | CH9: =BB9+BC9+BD9 -> -256.69 | CI9: =BI9+BJ9 -> 0 | CJ9: =AA9+AB9 -> 0 | CM9: =AV9+AW9 -> -14 | CN9: 2496.49 | CO9: -622.49 | CP9: 1874 | CQ9: 2495.63 | CR9: 8.0873 | CS9: 2495.63 | CT9: 199.65 | CU9: 1888.43
A10: =IFERROR(__xludf.DUMMYFUNCTION("""COMPUTED_VALUE"""),"ALIENE FORAPANI LOPES") -> ALIENE FORAPANI LOPES | C10: =IF(COUNTIF(A:A, H10)>0, "OK", "Incompleto") -> OK | D10: =AN10+BY10 -> 3493.1145 | E10: 45809 | F10: 07.391.921/0001-71 | G10: 299 | H10: ALIENE FORAPANI LOPES | I10: TECNICO EM SEGURANCA | J10: 44333 | K10: 2566.52 | L10: Salário Maternidade | M10: 2566.52 | O10: 0 | P10: 0 | AB10: 0 | AD10: 0 | AE10: 0 | AF10: 0 | AM10: 0.31 | AN10: =SUM(M10:AM10) -> 2566.83 | AQ10: 0 | AT10: -0.62 | AV10: 0 | AW10: 0 | BB10: 0 | BC10: 0 | BD10: 0 | BG10: -208.21 | BH10: 0 | BI10: 0 | BL10: =SUM(AO10:BK10) -> -208.83 | BM10: =AN10+BL10 -> 2358 | BN10: =K10/12*1 -> 213.87667 | BO10: =K10/12*1 -> 213.87667 | BP10: =BO10/3 -> 71.292222 | BQ10: =CQ10*CR10% -> 208.20893 | BR10: =CT10 -> 205.32 | BS10: =-(-CD10-AP10) -> 0 | BT10: =IF(CE10+AQ10<0, 0, CE10+AQ10) -> 0 | BU10: =CB10+CC10 -> 0 | BV10: =SUMIFS('SEGURO DE VIDA'!E:E, 'SEGURO DE VIDA'!D:D, H10, 'SEGURO DE VIDA'!G:G, E10) -> 13.71 | BW10: =SUMIFS(TREINAMENTOS!E:E, TREINAMENTOS!D:D, H10, TREINAMENTOS!G:G, E10) -> 0 | BX10: =SUMIFS(EXAMES!E:E, EXAMES!D:D, H10, EXAMES!G:G, E10) -> 0 | BY10: =SUM(BN10:BU10)+SUM(BV10:BX10) -> 926.28449 | CA10: ALIENE FORAPANI LOPES | CB10: =IF(SUM(BB10:BD10)+CF10<0, 0, SUM(BB10:BD10)+CF10) -> 0 | CC10: =IF(SUM(AV10:AW10)+CG10<0, 0, SUM(AV10:AW10)+CG10) -> 0 | CD10: =SUMIFS(ALIMENTAÇÃO!E:E, ALIMENTAÇÃO!D:D, H10, ALIMENTAÇÃO!G:G, E10) -> 0 | CE10: =SUMIFS(TRANSPORTE!E:E, TRANSPORTE!D:D, H10, TRANSPORTE!G:G, E10) -> 0 | CF10: =SUMIFS('PLANO DE SAÚDE'!E:E, 'PLANO DE SAÚDE'!D:D, H10, 'PLANO DE SAÚDE'!G:G, E10) -> 0 | CG10: =SUMIFS('PLANO ODONTO'!E:E, 'PLANO ODONTO'!D:D, H10, 'PLANO ODONTO'!G:G, E10) -> 0 | CH10: =BB10+BC10+BD10 -> 0 | CI10: =BI10+BJ10 -> 0 | CJ10: =AA10+AB10 -> 0 | CM10: =AV10+AW10 -> 0 | CN10: 2566.83 | CO10: -208.83 | CP10: 2358 | CQ10: 2566.52 | CR10: 8.1125 | CS10: 2566.52 | CT10: 205.32 | CU10: 1959.32
A11: =IFERROR(__xludf.DUMMYFUNCTION("""COMPUTED_VALUE"""),"ALISSON SANTOS DO NASCIMENTO") -> ALISSON SANTOS DO NASCIMENTO | C11: =IF(COUNTIF(A:A, H11)>0, "OK", "Incompleto") -> OK | D11: =AN11+BY11 -> 5062.6014 | E11: 45809 | F11: 07.391.921/0001-71 | G11: 176 | H11: ALLAM LUCAS MESQUITA DA SILVA | I11: TECNICO DE TELECOMUNI | J11: 42041 | K11: 3159.37 | M11: 3159.37 | O11: 0.84 | P11: 0 | W11: 0 | AB11: 0 | AD11: 0 | AE11: 0 | AF11: 0.21 | AM11: 0.27 | AN11: =SUM(M11:AM11) -> 3160.69 | AQ11: 0 | AT11: -0.03 | AV11: -14 | AW11: 0 | BB11: 0 | BC11: -2.01 | BD11: 0 | BG11: -272.65 | BH11: 0 | BI11: 0 | BL11: =SUM(AO11:BK11) -> -288.69 | BM11: =AN11+BL11 -> 2872 | BN11: =K11/12*1 -> 263.28083 | BO11: =K11/12*1 -> 263.28083 | BP11: =BO11/3 -> 87.760278 | BQ11: =CQ11*CR11% -> 272.64943 | BR11: =CT11 -> 252.83 | BS11: =-(-CD11-AP11) -> 630 | BT11: =IF(CE11+AQ11<0, 0, CE11+AQ11) -> 0 | BU11: =CB11+CC11 -> 118.4 | BV11: =SUMIFS('SEGURO DE VIDA'!E:E, 'SEGURO DE VIDA'!D:D, H11, 'SEGURO DE VIDA'!G:G, E11) -> 13.71 | BW11: =SUMIFS(TREINAMENTOS!E:E, TREINAMENTOS!D:D, H11, TREINAMENTOS!G:G, E11) -> 0 | BX11: =SUMIFS(EXAMES!E:E, EXAMES!D:D, H11, EXAMES!G:G, E11) -> 0 | BY11: =SUM(BN11:BU11)+SUM(BV11:BX11) -> 1901.9114 | CA11: ALLAM LUCAS MESQUITA DA SILVA | CB11: =IF(SUM(BB11:BD11)+CF11<0, 0, SUM(BB11:BD11)+CF11) -> 118.4 | CC11: =IF(SUM(AV11:AW11)+CG11<0, 0, SUM(AV11:AW11)+CG11) -> 0 | CD11: =SUMIFS(ALIMENTAÇÃO!E:E, ALIMENTAÇÃO!D:D, H11, ALIMENTAÇÃO!G:G, E11) -> 630 | CE11: =SUMIFS(TRANSPORTE!E:E, TRANSPORTE!D:D, H11, TRANSPORTE!G:G, E11) -> 0 | CF11: =SUMIFS('PLANO DE SAÚDE'!E:E, 'PLANO DE SAÚDE'!D:D, H11, 'PLANO DE SAÚDE'!G:G, E11) -> 120.41 | CG11: =SUMIFS('PLANO ODONTO'!E:E, 'PLANO ODONTO'!D:D, H11, 'PLANO ODONTO'!G:G, E11) -> 14 | CH11: =BB11+BC11+BD11 -> -2.01 | CI11: =BI11+BJ11 -> 0 | CJ11: =AA11+AB11 -> 0 | CM11: =AV11+AW11 -> -14 | CN11: 3160.69 | CO11: -288.69 | CP11: 2872 | CQ11: 3160.42 | CR11: 8.627 | CS11: 3160.42 | CT11: 252.83 | CU11: 2553.22
A12: =IFERROR(__xludf.DUMMYFUNCTION("""COMPUTED_VALUE"""),"ALLAM LUCAS MESQUITA DA SILVA") -> ALLAM LUCAS MESQUITA DA SILVA | C12: =IF(COUNTIF(A:A, H12)>0, "OK", "Incompleto") -> OK | D12: =AN12+BY12 -> 3291.3457 | E12: 45809 | F12: 07.391.921/0001-71 | G12: 3468 | H12: ALLAN DELFIM DOS SANTOS | I12: AUX INST REDE TEL JR | J12: 45566 | K12: 1518 | M12: 1518 | O12: 0 | P12: 455.4 | W12: 0 | AB12: 0 | AD12: 0 | AE12: 0 | AF12: 0 | AM12: 0.5 | AN12: =SUM(M12:AM12) -> 1973.9 | AQ12: 0 | AT12: -0.36 | AV12: -14 | AW12: 0 | BB12: 0 | BC12: -1.71 | BD12: 0 | BG12: -154.83 | BH12: 0 | BI12: 0 | BL12: =SUM(AO12:BK12) -> -170.9 | BM12: =AN12+BL12 -> 1803 | BN12: =K12/12*1 -> 126.5 | BO12: =K12/12*1 -> 126.5 | BP12: =BO12/3 -> 42.166667 | BQ12: =CQ12*CR12% -> 154.82902 | BR12: =CT12 -> 157.87 | BS12: =-(-CD12-AP12) -> 595 | BT12: =IF(CE12+AQ12<0, 0, CE12+AQ12) -> 0 | BU12: =CB12+CC12 -> 100.87 | BV12: =SUMIFS('SEGURO DE VIDA'!E:E, 'SEGURO DE VIDA'!D:D, H12, 'SEGURO DE VIDA'!G:G, E12) -> 13.71 | BW12: =SUMIFS(TREINAMENTOS!E:E, TREINAMENTOS!D:D, H12, TREINAMENTOS!G:G, E12) -> 0 | BX12: =SUMIFS(EXAMES!E:E, EXAMES!D:D, H12, EXAMES!G:G, E12) -> 0 | BY12: =SUM(BN12:BU12)+SUM(BV12:BX12) -> 1317.4457 | CA12: ALLAN DELFIM DOS SANTOS | CB12: =IF(SUM(BB12:BD12)+CF12<0, 0, SUM(BB12:BD12)+CF12) -> 100.87 | CC12: =IF(SUM(AV12:AW12)+CG12<0, 0, SUM(AV12:AW12)+CG12) -> 0 | CD12: =SUMIFS(ALIMENTAÇÃO!E:E, ALIMENTAÇÃO!D:D, H12, ALIMENTAÇÃO!G:G, E12) -> 595 | CE12: =SUMIFS(TRANSPORTE!E:E, TRANSPORTE!D:D, H12, TRANSPORTE!G:G, E12) -> 0 | CF12: =SUMIFS('PLANO DE SAÚDE'!E:E, 'PLANO DE SAÚDE'!D:D, H12, 'PLANO DE SAÚDE'!G:G, E12) -> 102.58 | CG12: =SUMIFS('PLANO ODONTO'!E:E, 'PLANO ODONTO'!D:D, H12, 'PLANO ODONTO'!G:G, E12) -> 14 | CH12: =BB12+BC12+BD12 -> -1.71 | CI12: =BI12+BJ12 -> 0 | CJ12: =AA12+AB12 -> 0 | CM12: =AV12+AW12 -> -14 | CN12: 1973.9 | CO12: -170.9 | CP12: 1803 | CQ12: 1973.4 | CR12: 7.8458 | CS12: 1973.4 | CT12: 157.87 | CU12: 1366.2
A13: =IFERROR(__xludf.DUMMYFUNCTION("""COMPUTED_VALUE"""),"ALLAN DELFIM DOS SANTOS") -> ALLAN DELFIM DOS SANTOS | C13: =IF(COUNTIF(A:A, H13)>0, "OK", "Incompleto") -> OK | D13: =AN13+BY13 -> 1883.8433 | E13: 45809 | F13: 07.391.921/0001-71 | G13: 3540 | H13: ANA BEATRIZ SAMPAIO TORRES DOS SANTOS | I13: ESTAGIARIO EM TELECOM | J13: 45810 | K13: 750 | M13: 725 | O13: 0 | P13: 0 | W13: 0 | AB13: 0 | AD13: 0 | AE13: 0 | AF13: 0 | AM13: 0 | AN13: =SUM(M13:AM13) -> 725 | AQ13: 0 | AT13: 0 | AV13: 0 | AW13: 0 | BB13: 0 | BC13: 0 | BD13: 0 | BG13: 0 | BH13: 0 | BI13: 0 | BL13: =SUM(AO13:BK13) -> 0 | BM13: =AN13+BL13 -> 725 | BN13: =K13/12*1 -> 62.5 | BO13: =K13/12*1 -> 62.5 | BP13: =BO13/3 -> 20.833333 | BQ13: =CQ13*CR13% -> 0 | BR13: =CT13 -> 0 | BS13: =-(-CD13-AP13) -> 665 | BT13: =IF(CE13+AQ13<0, 0, CE13+AQ13) -> 334.3 | BU13: =CB13+CC13 -> 0 | BV13: =SUMIFS('SEGURO DE VIDA'!E:E, 'SEGURO DE VIDA'!D:D, H13, 'SEGURO DE VIDA'!G:G, E13) -> 13.71 | BW13: =SUMIFS(TREINAMENTOS!E:E, TREINAMENTOS!D:D, H13, TREINAMENTOS!G:G, E13) -> 0 | BX13: =SUMIFS(EXAMES!E:E, EXAMES!D:D, H13, EXAMES!G:G, E13) -> 0 | BY13: =SUM(BN13:BU13)+SUM(BV13:BX13) -> 1158.8433 | CA13: ΑNA BEATRIZ SAMPAIO TORRES DC | CB13: =IF(SUM(BB13:BD13)+CF13<0, 0, SUM(BB13:BD13)+CF13) -> 0 | CC13: =IF(SUM(AV13:AW13)+CG13<0, 0, SUM(AV13:AW13)+CG13) -> 0 | CD13: =SUMIFS(ALIMENTAÇÃO!E:E, ALIMENTAÇÃO!D:D, H13, ALIMENTAÇÃO!G:G, E13) -> 665 | CE13: =SUMIFS(TRANSPORTE!E:E, TRANSPORTE!D:D, H13, TRANSPORTE!G:G, E13) -> 334.3 | CF13: =SUMIFS('PLANO DE SAÚDE'!E:E, 'PLANO DE SAÚDE'!D:D, H13, 'PLANO DE SAÚDE'!G:G, E13) -> 0 | CG13: =SUMIFS('PLANO ODONTO'!E:E, 'PLANO ODONTO'!D:D, H13, 'PLANO ODONTO'!G:G, E13) -> 0 | CH13: =BB13+BC13+BD13 -> 0 | CI13: =BI13+BJ13 -> 0 | CJ13: =AA13+AB13 -> 0 | CM13: =AV13+AW13 -> 0 | CN13: 725 | CO13: 0 | CP13: 725 | CQ13: 0 | CR13: 0 | CS13: 0 | CT13: 0 | CU13: 117.8
A14: =IFERROR(__xludf.DUMMYFUNCTION("""COMPUTED_VALUE"""),"AMANDA CRISTINA DE SOUZA ESTEVES") -> AMANDA CRISTINA DE SOUZA ESTEVES | C14: =IF(COUNTIF(A:A, H14)>0, "OK", "Incompleto") -> OK | D14: =AN14+BY14 -> 1691.3433 | E14: 45809 | F14: 07.391.921/0001-71 | G14: 3544 | H14: ANA BEATRIZ SOARES FERREIRA DE OLIVEIRA | I14: ESTAGIARIO EM TELECOM | J14: 45824 | K14: 750 | M14: 375 | O14: 0 | P14: 0 | W14: 0 | AB14: 0 | AD14: 0 | AE14: 0 | AF14: 0 | AM14: 0 | AN14: =SUM(M14:AM14) -> 375 | AQ14: 0 | AT14: 0 | AV14: 0 | AW14: 0 | BB14: 0 | BC14: 0 | BD14: 0 | BG14: 0 | BH14: 0 | BI14: 0 | BL14: =SUM(AO14:BK14) -> 0 | BM14: =AN14+BL14 -> 375 | BN14: =K14/12*1 -> 62.5 | BO14: =K14/12*1 -> 62.5 | BP14: =BO14/3 -> 20.833333 | BQ14: =CQ14*CR14% -> 0 | BR14: =CT14 -> 0 | BS14: =-(-CD14-AP14) -> 315 | BT14: =IF(CE14+AQ14<0, 0, CE14+AQ14) -> 256.5 | BU14: =CB14+CC14 -> 0 | BV14: =SUMIFS('SEGURO DE VIDA'!E:E, 'SEGURO DE VIDA'!D:D, H14, 'SEGURO DE VIDA'!G:G, E14) -> 0 | BW14: =SUMIFS(TREINAMENTOS!E:E, TREINAMENTOS!D:D, H14, TREINAMENTOS!G:G, E14) -> 0 | BX14: =SUMIFS(EXAMES!E:E, EXAMES!D:D, H14, EXAMES!G:G, E14) -> 599.01 | BY14: =SUM(BN14:BU14)+SUM(BV14:BX14) -> 1316.3433 | CA14: ΑNA BEATRIZ SOARES FERREIRA D | CB14: =IF(SUM(BB14:BD14)+CF14<0, 0, SUM(BB14:BD14)+CF14) -> 0 | CC14: =IF(SUM(AV14:AW14)+CG14<0, 0, SUM(AV14:AW14)+CG14) -> 0 | CD14: =SUMIFS(ALIMENTAÇÃO!E:E, ALIMENTAÇÃO!D:D, H14, ALIMENTAÇÃO!G:G, E14) -> 315 | CE14: =SUMIFS(TRANSPORTE!E:E, TRANSPORTE!D:D, H14, TRANSPORTE!G:G, E14) -> 256.5 | CF14: =SUMIFS('PLANO DE SAÚDE'!E:E, 'PLANO DE SAÚDE'!D:D, H14, 'PLANO DE SAÚDE'!G:G, E14) -> 0 | CG14: =SUMIFS('PLANO ODONTO'!E:E, 'PLANO ODONTO'!D:D, H14, 'PLANO ODONTO'!G:G, E14) -> 0 | CH14: =BB14+BC14+BD14 -> 0 | CI14: =BI14+BJ14 -> 0 | CJ14: =AA14+AB14 -> 0 | CM14: =AV14+AW14 -> 0 | CN14: 375 | CO14: 0 | CP14: 375 | CQ14: 0 | CR14: 0 | CS14: 0 | CT14: 0 | CU14: 0
A15: =IFERROR(__xludf.DUMMYFUNCTION("""COMPUTED_VALUE"""),"AMANDA GOMES ALFENAS") -> AMANDA GOMES ALFENAS | C15: =IF(COUNTIF(A:A, H15)>0, "OK", "Incompleto") -> OK | D15: =AN15+BY15 -> 3756.5092 | E15: 45809 | F15: 07.391.921/0001-71 | G15: 3527 | H15: ANDERSON PACHECO LOULA SALES | I15: Operador de Audio e Video | J15: 45771 | K15: 2239.36 | M15: 2239.36 | O15: 0 | P15: 0 | W15: 0 | AB15: 0 | AD15: 0 | AE15: 0 | AF15: 0 | AM15: 0.86 | AN15: =SUM(M15:AM15) -> 2240.22 | AQ15: -134.36 | AT15: -0.09 | AV15: 0 | AW15: 0 | BB15: 0 | BC15: 0 | BD15: 0 | BG15: -178.77 | BH15: 0 | BI15: 0 | BL15: =SUM(AO15:BK15) -> -313.22 | BM15: =AN15+BL15 -> 1927 | BN15: =K15/12*1 -> 186.61333 | BO15: =K15/12*1 -> 186.61333 | BP15: =BO15/3 -> 62.204444 | BQ15: =CQ15*CR15% -> 178.76811 | BR15: =CT15 -> 179.14 | BS15: =-(-CD15-AP15) -> 665 | BT15: =IF(CE15+AQ15<0, 0, CE15+AQ15) -> 44.24 | BU15: =CB15+CC15 -> 0 | BV15: =SUMIFS('SEGURO DE VIDA'!E:E, 'SEGURO DE VIDA'!D:D, H15, 'SEGURO DE VIDA'!G:G, E15) -> 13.71 | BW15: =SUMIFS(TREINAMENTOS!E:E, TREINAMENTOS!D:D, H15, TREINAMENTOS!G:G, E15) -> 0 | BX15: =SUMIFS(EXAMES!E:E, EXAMES!D:D, H15, EXAMES!G:G, E15) -> 0 | BY15: =SUM(BN15:BU15)+SUM(BV15:BX15) -> 1516.2892 | CA15: ANDERSON PACHECO LOULA SALE | CB15: =IF(SUM(BB15:BD15)+CF15<0, 0, SUM(BB15:BD15)+CF15) -> 0 | CC15: =IF(SUM(AV15:AW15)+CG15<0, 0, SUM(AV15:AW15)+CG15) -> 0 | CD15: =SUMIFS(ALIMENTAÇÃO!E:E, ALIMENTAÇÃO!D:D, H15, ALIMENTAÇÃO!G:G, E15) -> 665 | CE15: =SUMIFS(TRANSPORTE!E:E, TRANSPORTE!D:D, H15, TRANSPORTE!G:G, E15) -> 178.6 | CF15: =SUMIFS('PLANO DE SAÚDE'!E:E, 'PLANO DE SAÚDE'!D:D, H15, 'PLANO DE SAÚDE'!G:G, E15) -> 0 | CG15: =SUMIFS('PLANO ODONTO'!E:E, 'PLANO ODONTO'!D:D, H15, 'PLANO ODONTO'!G:G, E15) -> 0 | CH15: =BB15+BC15+BD15 -> 0 | CI15: =BI15+BJ15 -> 0 | CJ15: =AA15+AB15 -> 0 | CM15: =AV15+AW15 -> 0 | CN15: 2240.22 | CO15: -313.22 | CP15: 1927 | CQ15: 2239.36 | CR15: 7.983 | CS15: 2239.36 | CT15: 179.14 | CU15: 1632.16
A16: =IFERROR(__xludf.DUMMYFUNCTION("""COMPUTED_VALUE"""),"ANA BEATRIZ SAMPAIO TORRES DOS SANTOS") -> ANA BEATRIZ SAMPAIO TORRES DOS SANTOS | C16: =IF(COUNTIF(A:A, H16)>0, "OK", "Incompleto") -> OK | D16: =AN16+BY16 -> 4179.7805 | E16: 45809 | F16: 07.391.921/0001-71 | G16: 212 | H16: ANDERSON SANTOS PROMMERCHENKEL | I16: INST REDES TELEMATICAS | J16: 42569 | K16: 2495.63 | M16: 2495.63 | O16: 0 | P16: 0 | W16: 0 | AB16: 0 | AD16: 0 | AE16: 0 | AF16: 0 | AM16: 0.3 | AN16: =SUM(M16:AM16) -> 2495.93 | AQ16: 0 | AT16: -0.09 | AV16: 0 | AW16: 0 | BB16: 0 | BC16: -2.01 | BD16: 0 | BG16: -201.83 | BH16: 0 | BI16: 0 | BL16: =SUM(AO16:BK16) -> -203.93 | BM16: =AN16+BL16 -> 2292 | BN16: =K16/12*1 -> 207.96917 | BO16: =K16/12*1 -> 207.96917 | BP16: =BO16/3 -> 69.323056 | BQ16: =CQ16*CR16% -> 201.82908 | BR16: =CT16 -> 199.65 | BS16: =-(-CD16-AP16) -> 665 | BT16: =IF(CE16+AQ16<0, 0, CE16+AQ16) -> 0 | BU16: =CB16+CC16 -> 118.4 | BV16: =SUMIFS('SEGURO DE VIDA'!E:E, 'SEGURO DE VIDA'!D:D, H16, 'SEGURO DE VIDA'!G:G, E16) -> 13.71 | BW16: =SUMIFS(TREINAMENTOS!E:E, TREINAMENTOS!D:D, H16, TREINAMENTOS!G:G, E16) -> 0 | BX16: =SUMIFS(EXAMES!E:E, EXAMES!D:D, H16, EXAMES!G:G, E16) -> 0 | BY16: =SUM(BN16:BU16)+SUM(BV16:BX16) -> 1683.8505 | CA16: ANDERSON SANTOS PROMMERCHE | CB16: =IF(SUM(BB16:BD16)+CF16<0, 0, SUM(BB16:BD16)+CF16) -> 118.4 | CC16: =IF(SUM(AV16:AW16)+CG16<0, 0, SUM(AV16:AW16)+CG16) -> 0 | CD16: =SUMIFS(ALIMENTAÇÃO!E:E, ALIMENTAÇÃO!D:D, H16, ALIMENTAÇÃO!G:G, E16) -> 665 | CE16: =SUMIFS(TRANSPORTE!E:E, TRANSPORTE!D:D, H16, TRANSPORTE!G:G, E16) -> 0 | CF16: =SUMIFS('PLANO DE SAÚDE'!E:E, 'PLANO DE SAÚDE'!D:D, H16, 'PLANO DE SAÚDE'!G:G, E16) -> 120.41 | CG16: =SUMIFS('PLANO ODONTO'!E:E, 'PLANO ODONTO'!D:D, H16, 'PLANO ODONTO'!G:G, E16) -> 0 | CH16: =BB16+BC16+BD16 -> -2.01 | CI16: =BI16+BJ16 -> 0 | CJ16: =AA16+AB16 -> 0 | CM16: =AV16+AW16 -> 0 | CN16: 2495.93 | CO16: -203.93 | CP16: 2292 | CQ16: 2495.63 | CR16: 8.0873 | CS16: 2495.63 | CT16: 199.65 | CU16: 1888.43
A17: =IFERROR(__xludf.DUMMYFUNCTION("""COMPUTED_VALUE"""),"ANA BEATRIZ SOARES FERREIRA DE OLIVEIRA") -> ANA BEATRIZ SOARES FERREIRA DE OLIVEIRA | C17: =IF(COUNTIF(A:A, H17)>0, "OK", "Incompleto") -> OK | D17: =AN17+BY17 -> 7623.2213 | E17: 45809 | F17: 07.391.921/0001-71 | G17: 331 | H17: ANDERSON VIEIRA BARBOZA | I17: ELETRICISTA | J17: 44531 | K17: 2489.57 | M17: 2489.57 | O17: 0 | P17: 746.87 | W17: 0 | AB17: 623.9 | AD17: 1100.39 | AE17: 0 | AF17: 275.1 | AM17: 0.18 | AN17: =SUM(M17:AM17) -> 5236.01 | AQ17: -149.37 | AT17: -1.22 | AV17: -14 | AW17: 0 | BB17: 0 | BC17: 0 | BD17: 0 | BG17: -455.25 | BH17: -217.11 | BI17: -1313.06 | BL17: =SUM(AO17:BK17) -> -2150.01 | BM17: =AN17+BL17 -> 3086 | BN17: =K17/12*1 -> 207.46417 | BO17: =K17/12*1 -> 207.46417 | BP17: =BO17/3 -> 69.154722 | BQ17: =CQ17*CR17% -> 455.24822 | BR17: =CT17 -> 368.95 | BS17: =-(-CD17-AP17) -> 540 | BT17: =IF(CE17+AQ17<0, 0, CE17+AQ17) -> 36.83 | BU17: =CB17+CC17 -> 488.39 | BV17: =SUMIFS('SEGURO DE VIDA'!E:E, 'SEGURO DE VIDA'!D:D, H17, 'SEGURO DE VIDA'!G:G, E17) -> 13.71 | BW17: =SUMIFS(TREINAMENTOS!E:E, TREINAMENTOS!D:D, H17, TREINAMENTOS!G:G, E17) -> 0 | BX17: =SUMIFS(EXAMES!E:E, EXAMES!D:D, H17, EXAMES!G:G, E17) -> 0 | BY17: =SUM(BN17:BU17)+SUM(BV17:BX17) -> 2387.2113 | CA17: ANDERSON VIEIRA BARBOZA | CB17: =IF(SUM(BB17:BD17)+CF17<0, 0, SUM(BB17:BD17)+CF17) -> 488.39 | CC17: =IF(SUM(AV17:AW17)+CG17<0, 0, SUM(AV17:AW17)+CG17) -> 0 | CD17: =SUMIFS(ALIMENTAÇÃO!E:E, ALIMENTAÇÃO!D:D, H17, ALIMENTAÇÃO!G:G, E17) -> 540 | CE17: =SUMIFS(TRANSPORTE!E:E, TRANSPORTE!D:D, H17, TRANSPORTE!G:G, E17) -> 186.2 | CF17: =SUMIFS('PLANO DE SAÚDE'!E:E, 'PLANO DE SAÚDE'!D:D, H17, 'PLANO DE SAÚDE'!G:G, E17) -> 488.39 | CG17: =SUMIFS('PLANO ODONTO'!E:E, 'PLANO ODONTO'!D:D, H17, 'PLANO ODONTO'!G:G, E17) -> 14 | CH17: =BB17+BC17+BD17 -> 0 | CI17: =BI17+BJ17 -> -1313.06 | CJ17: =AA17+AB17 -> 623.9 | CM17: =AV17+AW17 -> -14 | CN17: 5236.01 | CO17: -2150.01 | CP17: 3086 | CQ17: 4611.93 | CR17: 9.8711 | CS17: 4611.93 | CT17: 368.95 | CU17: 3967.09
A18: =IFERROR(__xludf.DUMMYFUNCTION("""COMPUTED_VALUE"""),"ANA CAROLINA MARQUES SERAFIM") -> ANA CAROLINA MARQUES SERAFIM | C18: =IF(COUNTIF(A:A, H18)>0, "OK", "Incompleto") -> OK | D18: =AN18+BY18 -> 4523.7805 | E18: 45809 | F18: 07.391.921/0001-71 | G18: 220 | H18: ANDRE LUIZ PEREIRA COSTA | I18: INST REDES TELEMATICAS | J18: 43060 | K18: 2495.63 | M18: 2495.63 | O18: 0 | P18: 0 | W18: 0 | AB18: 0 | AD18: 0 | AE18: 0 | AF18: 0 | AM18: 0.23 | AN18: =SUM(M18:AM18) -> 2495.86 | AQ18: -149.74 | AT18: -0.74 | AV18: -14 | AW18: -14 | BB18: 0 | BC18: -34.55 | BD18: 0 | BG18: -201.83 | BH18: 0 | BI18: 0 | BL18: =SUM(AO18:BK18) -> -414.86 | BM18: =AN18+BL18 -> 2081 | BN18: =K18/12*1 -> 207.96917 | BO18: =K18/12*1 -> 207.96917 | BP18: =BO18/3 -> 69.323056 | BQ18: =CQ18*CR18% -> 201.82908 | BR18: =CT18 -> 199.65 | BS18: =-(-CD18-AP18) -> 630 | BT18: =IF(CE18+AQ18<0, 0, CE18+AQ18) -> 163.76 | BU18: =CB18+CC18 -> 231.59 | BV18: =SUMIFS('SEGURO DE VIDA'!E:E, 'SEGURO DE VIDA'!D:D, H18, 'SEGURO DE VIDA'!G:G, E18) -> 13.71 | BW18: =SUMIFS(TREINAMENTOS!E:E, TREINAMENTOS!D:D, H18, TREINAMENTOS!G:G, E18) -> 0 | BX18: =SUMIFS(EXAMES!E:E, EXAMES!D:D, H18, EXAMES!G:G, E18) -> 102.12 | BY18: =SUM(BN18:BU18)+SUM(BV18:BX18) -> 2027.9205 | CA18: ANDRE LUIZ PEREIRA COSTA | CB18: =IF(SUM(BB18:BD18)+CF18<0, 0, SUM(BB18:BD18)+CF18) -> 206.41 | CC18: =IF(SUM(AV18:AW18)+CG18<0, 0, SUM(AV18:AW18)+CG18) -> 25.18 | CD18: =SUMIFS(ALIMENTAÇÃO!E:E, ALIMENTAÇÃO!D:D, H18, ALIMENTAÇÃO!G:G, E18) -> 630 | CE18: =SUMIFS(TRANSPORTE!E:E, TRANSPORTE!D:D, H18, TRANSPORTE!G:G, E18) -> 313.5 | CF18: =SUMIFS('PLANO DE SAÚDE'!E:E, 'PLANO DE SAÚDE'!D:D, H18, 'PLANO DE SAÚDE'!G:G, E18) -> 240.96 | CG18: =SUMIFS('PLANO ODONTO'!E:E, 'PLANO ODONTO'!D:D, H18, 'PLANO ODONTO'!G:G, E18) -> 53.18 | CH18: =BB18+BC18+BD18 -> -34.55 | CI18: =BI18+BJ18 -> 0 | CJ18: =AA18+AB18 -> 0 | CM18: =AV18+AW18 -> -28 | CN18: 2495.86 | CO18: -414.86 | CP18: 2081 | CQ18: 2495.63 | CR18: 8.0873 | CS18: 2495.63 | CT18: 199.65 | CU18: 1888.43
A19: =IFERROR(__xludf.DUMMYFUNCTION("""COMPUTED_VALUE"""),"ANDERSON BARBOSA PEREIRA") -> ANDERSON BARBOSA PEREIRA | C19: =IF(COUNTIF(A:A, H19)>0, "OK", "Incompleto") -> OK | D19: =AN19+BY19 -> 4063.6334 | E19: 45809 | F19: 07.391.921/0001-71 | G19: 3504 | H19: ANGÉLICA DE FRANÇA RAMOS | I19: ASSIST PROJETOS | J19: 45677 | K19: 2390.42 | M19: 2390.42 | O19: 0 | P19: 0 | W19: 0 | AB19: 0 | AD19: 0 | AE19: 0 | AF19: 0 | AM19: 0.89 | AN19: =SUM(M19:AM19) -> 2391.31 | AQ19: 0 | AT19: -0.87 | AV19: 0 | AW19: 0 | BB19: 0 | BC19: -100.08 | BD19: 0 | BG19: -192.36 | BH19: 0 | BI19: 0 | BL19: =SUM(AO19:BK19) -> -293.31 | BM19: =AN19+BL19 -> 2098 | BN19: =K19/12*1 -> 199.20167 | BO19: =K19/12*1 -> 199.20167 | BP19: =BO19/3 -> 66.400556 | BQ19: =CQ19*CR19% -> 192.35949 | BR19: =CT19 -> 191.23 | BS19: =-(-CD19-AP19) -> 510 | BT19: =IF(CE19+AQ19<0, 0, CE19+AQ19) -> 0 | BU19: =CB19+CC19 -> 300.22 | BV19: =SUMIFS('SEGURO DE VIDA'!E:E, 'SEGURO DE VIDA'!D:D, H19, 'SEGURO DE VIDA'!G:G, E19) -> 13.71 | BW19: =SUMIFS(TREINAMENTOS!E:E, TREINAMENTOS!D:D, H19, TREINAMENTOS!G:G, E19) -> 0 | BX19: =SUMIFS(EXAMES!E:E, EXAMES!D:D, H19, EXAMES!G:G, E19) -> 0 | BY19: =SUM(BN19:BU19)+SUM(BV19:BX19) -> 1672.3234 | CA19: ANGELICA DE FRANCA RAMOS | CB19: =IF(SUM(BB19:BD19)+CF19<0, 0, SUM(BB19:BD19)+CF19) -> 300.22 | CC19: =IF(SUM(AV19:AW19)+CG19<0, 0, SUM(AV19:AW19)+CG19) -> 0 | CD19: =SUMIFS(ALIMENTAÇÃO!E:E, ALIMENTAÇÃO!D:D, H19, ALIMENTAÇÃO!G:G, E19) -> 510 | CE19: =SUMIFS(TRANSPORTE!E:E, TRANSPORTE!D:D, H19, TRANSPORTE!G:G, E19) -> 0 | CF19: =SUMIFS('PLANO DE SAÚDE'!E:E, 'PLANO DE SAÚDE'!D:D, H19, 'PLANO DE SAÚDE'!G:G, E19) -> 400.3 | CG19: =SUMIFS('PLANO ODONTO'!E:E, 'PLANO ODONTO'!D:D, H19, 'PLANO ODONTO'!G:G, E19) -> 0 | CH19: =BB19+BC19+BD19 -> -100.08 | CI19: =BI19+BJ19 -> 0 | CJ19: =AA19+AB19 -> 0 | CM19: =AV19+AW19 -> 0 | CN19: 2391.31 | CO19: -293.31 | CP19: 2098 | CQ19: 2390.42 | CR19: 8.0471 | CS19: 2390.42 | CT19: 191.23 | CU19: 1783.22
A20: =IFERROR(__xludf.DUMMYFUNCTION("""COMPUTED_VALUE"""),"ANDERSON FERREIRA SANTANA") -> ANDERSON FERREIRA SANTANA | C20: =IF(COUNTIF(A:A, H20)>0, "OK", "Incompleto") -> OK | D20: =AN20+BY20 -> 3665.8117 | E20: 45809 | F20: 20.258.413/0001-88 | G20: 13 | H20: ANTONIO DIOGO DA SILVA TEIXEIRA | I20: TECNICO DE MANUTENCAC | J20: 43592 | K20: 2562.79 | L20: Férias | M20: 1964.81 | AC20: 0 | AD20: 0 | AE20: 0 | AF20: 0 | AM20: 0.83 | AN20: =SUM(M20:AM20) -> 1965.64 | AP20: -6.65 | AQ20: -117.89 | AR20: 0 | AT20: -0.72 | AV20: -14 | BB20: -52.64 | BC20: -2.24 | BD20: -452.47 | BG20: -166.03 | BH20: 0 | BL20: =SUM(AO20:BK20) -> -812.64 | BM20: =AN20+BL20 -> 1153 | BN20: =K20/12*1 -> 213.56583 | BO20: =K20/12*1 -> 213.56583 | BP20: =BO20/3 -> 71.188611 | BQ20: =CQ20*CR20% -> 160.72146 | BR20: =CT20 -> 157.18 | BS20: =-(-CD20-AP20) -> 658.35 | BT20: =IF(CE20+AQ20<0, 0, CE20+AQ20) -> 207.01 | BU20: =CB20+CC20 -> 0 | BV20: =SUMIFS('SEGURO DE VIDA'!E:E, 'SEGURO DE VIDA'!D:D, H20, 'SEGURO DE VIDA'!G:G, E20) -> 18.59 | BW20: =SUMIFS(TREINAMENTOS!E:E, TREINAMENTOS!D:D, H20, TREINAMENTOS!G:G, E20) -> 0 | BX20: =SUMIFS(EXAMES!E:E, EXAMES!D:D, H20, EXAMES!G:G, E20) -> 0 | BY20: =SUM(BN20:BU20)+SUM(BV20:BX20) -> 1700.1717 | CA20: ANTONIO DIOGO DA SILVA TEIXEIRA | CB20: =IF(SUM(BB20:BD20)+CF20<0, 0, SUM(BB20:BD20)+CF20) -> 0 | CC20: =IF(SUM(AV20:AW20)+CG20<0, 0, SUM(AV20:AW20)+CG20) -> 0 | CD20: =SUMIFS(ALIMENTAÇÃO!E:E, ALIMENTAÇÃO!D:D, H20, ALIMENTAÇÃO!G:G, E20) -> 665 | CE20: =SUMIFS(TRANSPORTE!E:E, TRANSPORTE!D:D, H20, TRANSPORTE!G:G, E20) -> 324.9 | CF20: =SUMIFS('PLANO DE SAÚDE'!E:E, 'PLANO DE SAÚDE'!D:D, H20, 'PLANO DE SAÚDE'!G:G, E20) -> 458.61 | CG20: =SUMIFS('PLANO ODONTO'!E:E, 'PLANO ODONTO'!D:D, H20, 'PLANO ODONTO'!G:G, E20) -> 14 | CH20: =BB20+BC20+BD20 -> -507.35 | CI20: =BI20+BJ20 -> 0 | CJ20: =AA20+AB20 -> 0 | CM20: =AV20+AW20 -> -14 | CN20: 1965.64 | CO20: -812.64 | CP20: 1153 | CQ20: 1964.81 | CR20: 8.18 | CS20: 1964.81 | CT20: 157.18 | CU20: 1357.61
A21: =IFERROR(__xludf.DUMMYFUNCTION("""COMPUTED_VALUE"""),"ANDERSON PACHECO LOULA SALES") -> ANDERSON PACHECO LOULA SALES | C21: =IF(COUNTIF(A:A, H21)>0, "OK", "Incompleto") -> OK | D21: =AN21+BY21 -> 4134.5646 | E21: 45809 | F21: 07.391.921/0001-71 | G21: 3526 | H21: ARTHUR CASSILHAS DA MATA | I21: INSTALADOR JUNIOR | J21: 45761 | K21: 1700 | L21: Atestado | M21: 1700 | O21: 0 | P21: 510 | W21: 0 | AB21: 0 | AD21: 259.68 | AE21: 182.33 | AF21: 110.5 | AM21: 0.94 | AN21: =SUM(M21:AM21) -> 2763.45 | AQ21: 0 | AT21: -0.6 | AV21: 0 | AW21: 0 | BB21: 0 | BC21: 0 | BD21: 0 | BG21: -225.85 | BH21: 0 | BI21: 0 | BL21: =SUM(AO21:BK21) -> -226.45 | BM21: =AN21+BL21 -> 2537 | BN21: =K21/12*1 -> 141.66667 | BO21: =K21/12*1 -> 141.66667 | BP21: =BO21/3 -> 47.222222 | BQ21: =CQ21*CR21% -> 225.84901 | BR21: =CT21 -> 221 | BS21: =-(-CD21-AP21) -> 570 | BT21: =IF(CE21+AQ21<0, 0, CE21+AQ21) -> 0 | BU21: =CB21+CC21 -> 0 | BV21: =SUMIFS('SEGURO DE VIDA'!E:E, 'SEGURO DE VIDA'!D:D, H21, 'SEGURO DE VIDA'!G:G, E21) -> 13.71 | BW21: =SUMIFS(TREINAMENTOS!E:E, TREINAMENTOS!D:D, H21, TREINAMENTOS!G:G, E21) -> 0 | BX21: =SUMIFS(EXAMES!E:E, EXAMES!D:D, H21, EXAMES!G:G, E21) -> 10 | BY21: =SUM(BN21:BU21)+SUM(BV21:BX21) -> 1371.1146 | CA21: ARTHUR CASSILHAS DA ΜΑΤΑ | CB21: =IF(SUM(BB21:BD21)+CF21<0, 0, SUM(BB21:BD21)+CF21) -> 0 | CC21: =IF(SUM(AV21:AW21)+CG21<0, 0, SUM(AV21:AW21)+CG21) -> 0 | CD21: =SUMIFS(ALIMENTAÇÃO!E:E, ALIMENTAÇÃO!D:D, H21, ALIMENTAÇÃO!G:G, E21) -> 570 | CE21: =SUMIFS(TRANSPORTE!E:E, TRANSPORTE!D:D, H21, TRANSPORTE!G:G, E21) -> 0 | CF21: =SUMIFS('PLANO DE SAÚDE'!E:E, 'PLANO DE SAÚDE'!D:D, H21, 'PLANO DE SAÚDE'!G:G, E21) -> 0 | CG21: =SUMIFS('PLANO ODONTO'!E:E, 'PLANO ODONTO'!D:D, H21, 'PLANO ODONTO'!G:G, E21) -> 0 | CH21: =BB21+BC21+BD21 -> 0 | CI21: =BI21+BJ21 -> 0 | CJ21: =AA21+AB21 -> 0 | CM21: =AV21+AW21 -> 0 | CN21: 2763.45 | CO21: -226.45 | CP21: 2537 | CQ21: 2762.51 | CR21: 8.1755 | CS21: 2762.51 | CT21: 221 | CU21: 2155.31
A22: =IFERROR(__xludf.DUMMYFUNCTION("""COMPUTED_VALUE"""),"ANDERSON SANTOS PROMMERCHENKEL") -> ANDERSON SANTOS PROMMERCHENKEL | C22: =IF(COUNTIF(A:A, H22)>0, "OK", "Incompleto") -> OK | D22: =AN22+BY22 -> 1737.5433 | E22: 45809 | F22: 07.391.921/0001-71 | G22: 3541 | H22: ARTHUR RODRIGUES RANGEL | I22: ESTAGIARIO EM TELECOM | J22: 45810 | K22: 750 | M22: 725 | O22: 0 | P22: 0 | W22: 0 | AB22: 0 | AD22: 0 | AE22: 0 | AF22: 0 | AM22: 0 | AN22: =SUM(M22:AM22) -> 725 | AQ22: 0 | AT22: 0 | AV22: 0 | AW22: 0 | BB22: 0 | BC22: 0 | BD22: 0 | BG22: 0 | BH22: 0 | BI22: 0 | BL22: =SUM(AO22:BK22) -> 0 | BM22: =AN22+BL22 -> 725 | BN22: =K22/12*1 -> 62.5 | BO22: =K22/12*1 -> 62.5 | BP22: =BO22/3 -> 20.833333 | BQ22: =CQ22*CR22% -> 0 | BR22: =CT22 -> 0 | BS22: =-(-CD22-AP22) -> 665 | BT22: =IF(CE22+AQ22<0, 0, CE22+AQ22) -> 188 | BU22: =CB22+CC22 -> 0 | BV22: =SUMIFS('SEGURO DE VIDA'!E:E, 'SEGURO DE VIDA'!D:D, H22, 'SEGURO DE VIDA'!G:G, E22) -> 13.71 | BW22: =SUMIFS(TREINAMENTOS!E:E, TREINAMENTOS!D:D, H22, TREINAMENTOS!G:G, E22) -> 0 | BX22: =SUMIFS(EXAMES!E:E, EXAMES!D:D, H22, EXAMES!G:G, E22) -> 0 | BY22: =SUM(BN22:BU22)+SUM(BV22:BX22) -> 1012.5433 | CA22: ARTHUR RODRIGUES RANGEL | CB22: =IF(SUM(BB22:BD22)+CF22<0, 0, SUM(BB22:BD22)+CF22) -> 0 | CC22: =IF(SUM(AV22:AW22)+CG22<0, 0, SUM(AV22:AW22)+CG22) -> 0 | CD22: =SUMIFS(ALIMENTAÇÃO!E:E, ALIMENTAÇÃO!D:D, H22, ALIMENTAÇÃO!G:G, E22) -> 665 | CE22: =SUMIFS(TRANSPORTE!E:E, TRANSPORTE!D:D, H22, TRANSPORTE!G:G, E22) -> 188 | CF22: =SUMIFS('PLANO DE SAÚDE'!E:E, 'PLANO DE SAÚDE'!D:D, H22, 'PLANO DE SAÚDE'!G:G, E22) -> 0 | CG22: =SUMIFS('PLANO ODONTO'!E:E, 'PLANO ODONTO'!D:D, H22, 'PLANO ODONTO'!G:G, E22) -> 0 | CH22: =BB22+BC22+BD22 -> 0 | CI22: =BI22+BJ22 -> 0 | CJ22: =AA22+AB22 -> 0 | CM22: =AV22+AW22 -> 0 | CN22: 725 | CO22: 0 | CP22: 725 | CQ22: 0 | CR22: 0 | CS22: 0 | CT22: 0 | CU22: 117.8
A23: =IFERROR(__xludf.DUMMYFUNCTION("""COMPUTED_VALUE"""),"ANDERSON VIEIRA BARBOZA") -> ANDERSON VIEIRA BARBOZA | C23: =IF(COUNTIF(A:A, H23)>0, "OK", "Incompleto") -> OK | D23: =AN23+BY23 -> 4870.5208 | E23: 45809 | F23: 07.391.921/0001-71 | G23: 347 | H23: ARTHUR SOUZA LEMOS PINHEIRO | I23: ANALISTA DE TELECOMUN | J23: 44713 | K23: 3034.3 | M23: 3034.3 | O23: 0 | P23: 0 | W23: 0 | AB23: 0 | AD23: 0 | AE23: 0 | AF23: 0 | AM23: 0.13 | AN23: =SUM(M23:AM23) -> 3034.43 | AQ23: 0 | AT23: -0.91 | AV23: 0 | AW23: 0 | BB23: 0 | BC23: 0 | BD23: 0 | BG23: -257.52 | BH23: 0 | BI23: 0 | BL23: =SUM(AO23:BK23) -> -258.43 | BM23: =AN23+BL23 -> 2776 | BN23: =K23/12*1 -> 252.85833 | BO23: =K23/12*1 -> 252.85833 | BP23: =BO23/3 -> 84.286111 | BQ23: =CQ23*CR23% -> 257.51801 | BR23: =CT23 -> 242.74 | BS23: =-(-CD23-AP23) -> 630 | BT23: =IF(CE23+AQ23<0, 0, CE23+AQ23) -> 0 | BU23: =CB23+CC23 -> 0 | BV23: =SUMIFS('SEGURO DE VIDA'!E:E, 'SEGURO DE VIDA'!D:D, H23, 'SEGURO DE VIDA'!G:G, E23) -> 13.71 | BW23: =SUMIFS(TREINAMENTOS!E:E, TREINAMENTOS!D:D, H23, TREINAMENTOS!G:G, E23) -> 0 | BX23: =SUMIFS(EXAMES!E:E, EXAMES!D:D, H23, EXAMES!G:G, E23) -> 102.12 | BY23: =SUM(BN23:BU23)+SUM(BV23:BX23) -> 1836.0908 | CA23: ARTHUR SOUZA LEMOS PINHEIRO | CB23: =IF(SUM(BB23:BD23)+CF23<0, 0, SUM(BB23:BD23)+CF23) -> 0 | CC23: =IF(SUM(AV23:AW23)+CG23<0, 0, SUM(AV23:AW23)+CG23) -> 0 | CD23: =SUMIFS(ALIMENTAÇÃO!E:E, ALIMENTAÇÃO!D:D, H23, ALIMENTAÇÃO!G:G, E23) -> 630 | CE23: =SUMIFS(TRANSPORTE!E:E, TRANSPORTE!D:D, H23, TRANSPORTE!G:G, E23) -> 0 | CF23: =SUMIFS('PLANO DE SAÚDE'!E:E, 'PLANO DE SAÚDE'!D:D, H23, 'PLANO DE SAÚDE'!G:G, E23) -> 0 | CG23: =SUMIFS('PLANO ODONTO'!E:E, 'PLANO ODONTO'!D:D, H23, 'PLANO ODONTO'!G:G, E23) -> 0 | CH23: =BB23+BC23+BD23 -> 0 | CI23: =BI23+BJ23 -> 0 | CJ23: =AA23+AB23 -> 0 | CM23: =AV23+AW23 -> 0 | CN23: 3034.43 | CO23: -258.43 | CP23: 2776 | CQ23: 3034.3 | CR23: 8.4869 | CS23: 3034.3 | CT23: 242.74 | CU23: 2427.1
A24: =IFERROR(__xludf.DUMMYFUNCTION("""COMPUTED_VALUE"""),"ANDRE LUIZ PEREIRA COSTA") -> ANDRE LUIZ PEREIRA COSTA | C24: =IF(COUNTIF(A:A, H24)>0, "OK", "Incompleto") -> OK | D24: =AN24+BY24 -> 3460.9 | E24: 45809 | F24: 07.391.921/0001-71 | G24: 3514 | H24: ARTUR OLIVEIRA CABRAL | I24: INSTALADOR | J24: 45726 | K24: 1800 | M24: 1800 | O24: 0 | P24: 0 | W24: 0 | AB24: 0 | AD24: 0 | AE24: 0 | AF24: 0 | AM24: 0.66 | AN24: =SUM(M24:AM24) -> 1800.66 | AQ24: -108 | AT24: -0.97 | AV24: -14 | AW24: 0 | BB24: -21.45 | BC24: -2.01 | BD24: 0 | BG24: -139.23 | BH24: 0 | BI24: 0 | BL24: =SUM(AO24:BK24) -> -285.66 | BM24: =AN24+BL24 -> 1515 | BN24: =K24/12*1 -> 150 | BO24: =K24/12*1 -> 150 | BP24: =BO24/3 -> 50 | BQ24: =CQ24*CR24% -> 139.23 | BR24: =CT24 -> 144 | BS24: =-(-CD24-AP24) -> 630 | BT24: =IF(CE24+AQ24<0, 0, CE24+AQ24) -> 4.8 | BU24: =CB24+CC24 -> 118.4 | BV24: =SUMIFS('SEGURO DE VIDA'!E:E, 'SEGURO DE VIDA'!D:D, H24, 'SEGURO DE VIDA'!G:G, E24) -> 13.71 | BW24: =SUMIFS(TREINAMENTOS!E:E, TREINAMENTOS!D:D, H24, TREINAMENTOS!G:G, E24) -> 260.1 | BX24: =SUMIFS(EXAMES!E:E, EXAMES!D:D, H24, EXAMES!G:G, E24) -> 0 | BY24: =SUM(BN24:BU24)+SUM(BV24:BX24) -> 1660.24 | CA24: ARTUR OLIVEIRA CABRAL | CB24: =IF(SUM(BB24:BD24)+CF24<0, 0, SUM(BB24:BD24)+CF24) -> 118.4 | CC24: =IF(SUM(AV24:AW24)+CG24<0, 0, SUM(AV24:AW24)+CG24) -> 0 | CD24: =SUMIFS(ALIMENTAÇÃO!E:E, ALIMENTAÇÃO!D:D, H24, ALIMENTAÇÃO!G:G, E24) -> 630 | CE24: =SUMIFS(TRANSPORTE!E:E, TRANSPORTE!D:D, H24, TRANSPORTE!G:G, E24) -> 112.8 | CF24: =SUMIFS('PLANO DE SAÚDE'!E:E, 'PLANO DE SAÚDE'!D:D, H24, 'PLANO DE SAÚDE'!G:G, E24) -> 141.86 | CG24: =SUMIFS('PLANO ODONTO'!E:E, 'PLANO ODONTO'!D:D, H24, 'PLANO ODONTO'!G:G, E24) -> 14 | CH24: =BB24+BC24+BD24 -> -23.46 | CI24: =BI24+BJ24 -> 0 | CJ24: =AA24+AB24 -> 0 | CM24: =AV24+AW24 -> -14 | CN24: 1800.66 | CO24: -285.66 | CP24: 1515 | CQ24: 1800 | CR24: 7.735 | CS24: 1800 | CT24: 144 | CU24: 1192.8
A25: =IFERROR(__xludf.DUMMYFUNCTION("""COMPUTED_VALUE"""),"ANGÉLICA DE FRANÇA RAMOS") -> ANGÉLICA DE FRANÇA RAMOS | C25: =IF(COUNTIF(A:A, H25)>0, "OK", "Incompleto") -> OK | D25: =AN25+BY25 -> 5987.3264 | E25: 45809 | F25: 07.391.921/0001-71 | G25: 180 | H25: AUREA CRISTINA DE OLIVEIRA BERNARDES | I25: ANALISTA DE TELECOMUN | J25: 42248 | K25: 3741.16 | M25: 3741.16 | O25: 0 | P25: 0 | T25: 0 | Y25: 0 | AA25: 0 | AB25: 0 | AD25: 0 | AE25: 0 | AF25: 0 | AJ25: 0 | AM25: 0.69 | AN25: =SUM(M25:AM25) -> 3741.85 | AP25: 0 | AQ25: -224.47 | AT25: -0.46 | AV25: 0 | AY25: -37.41 | BB25: 0 | BC25: -2.24 | BF25: 0 | BG25: -342.34 | BH25: -75.93 | BI25: 0 | BL25: =SUM(AO25:BK25) -> -682.85 | BM25: =AN25+BL25 -> 3059 | BN25: =K25/12*1 -> 311.76333 | BO25: =K25/12*1 -> 311.76333 | BP25: =BO25/3 -> 103.92111 | BQ25: =CQ25*CR25% -> 342.33859 | BR25: =CT25 -> 299.29 | BS25: =-(-CD25-AP25) -> 630 | BT25: =IF(CE25+AQ25<0, 0, CE25+AQ25) -> 100.43 | BU25: =CB25+CC25 -> 132.26 | BV25: =SUMIFS('SEGURO DE VIDA'!E:E, 'SEGURO DE VIDA'!D:D, H25, 'SEGURO DE VIDA'!G:G, E25) -> 13.71 | BW25: =SUMIFS(TREINAMENTOS!E:E, TREINAMENTOS!D:D, H25, TREINAMENTOS!G:G, E25) -> 0 | BX25: =SUMIFS(EXAMES!E:E, EXAMES!D:D, H25, EXAMES!G:G, E25) -> 0 | BY25: =SUM(BN25:BU25)+SUM(BV25:BX25) -> 2245.4764 | CA25: AUREA CRISTINA DE OLIVEIRA BER | CB25: =IF(SUM(BB25:BD25)+CF25<0, 0, SUM(BB25:BD25)+CF25) -> 132.26 | CC25: =IF(SUM(AV25:AW25)+CG25<0, 0, SUM(AV25:AW25)+CG25) -> 0 | CD25: =SUMIFS(ALIMENTAÇÃO!E:E, ALIMENTAÇÃO!D:D, H25, ALIMENTAÇÃO!G:G, E25) -> 630 | CE25: =SUMIFS(TRANSPORTE!E:E, TRANSPORTE!D:D, H25, TRANSPORTE!G:G, E25) -> 324.9 | CF25: =SUMIFS('PLANO DE SAÚDE'!E:E, 'PLANO DE SAÚDE'!D:D, H25, 'PLANO DE SAÚDE'!G:G, E25) -> 134.5 | CG25: =SUMIFS('PLANO ODONTO'!E:E, 'PLANO ODONTO'!D:D, H25, 'PLANO ODONTO'!G:G, E25) -> 0 | CH25: =BB25+BC25+BD25 -> -2.24 | CI25: =BI25+BJ25 -> 0 | CJ25: =AA25+AB25 -> 0 | CM25: =AV25+AW25 -> 0 | CN25: 3741.85 | CO25: -682.85 | CP25: 3059 | CQ25: 3741.16 | CR25: 9.1506 | CS25: 3741.16 | CT25: 299.29 | CU25: 3133.96
A26: =IFERROR(__xludf.DUMMYFUNCTION("""COMPUTED_VALUE"""),"ANNA BEATRIZ DOS SANTOS CARNEIRO SILVA") -> ANNA BEATRIZ DOS SANTOS CARNEIRO SILVA | C26: =IF(COUNTIF(A:A, H26)>0, "OK", "Incompleto") -> OK | D26: =AN26+BY26 -> 4579.7325 | E26: 45809 | F26: 20.258.413/0001-88 | G26: 21 | H26: BIANCA RODRIGUES DA SILVEIRA | I26: ASSISTENTE ADMINISTRAT | J26: 44200 | K26: 3200 | M26: 3200 | AC26: 0 | AD26: 0 | AE26: 0 | AF26: 0 | AM26: 0.31 | AN26: =SUM(M26:AM26) -> 3200.31 | AP26: -5.6 | AQ26: 0 | AR26: 0 | AT26: -0.01 | AV26: -14 | BB26: 0 | BC26: 0 | BD26: 0 | BG26: -277.4 | BH26: -12.3 | BL26: =SUM(AO26:BK26) -> -309.31 | BM26: =AN26+BL26 -> 2891 | BN26: =K26/12*1 -> 266.66667 | BO26: =K26/12*1 -> 266.66667 | BP26: =BO26/3 -> 88.888889 | BQ26: =CQ26*CR26% -> 98.880309 | BR26: =CT26 -> 85.33 | BS26: =-(-CD26-AP26) -> 554.4 | BT26: =IF(CE26+AQ26<0, 0, CE26+AQ26) -> 0 | BU26: =CB26+CC26 -> 0 | BV26: =SUMIFS('SEGURO DE VIDA'!E:E, 'SEGURO DE VIDA'!D:D, H26, 'SEGURO DE VIDA'!G:G, E26) -> 18.59 | BW26: =SUMIFS(TREINAMENTOS!E:E, TREINAMENTOS!D:D, H26, TREINAMENTOS!G:G, E26) -> 0 | BX26: =SUMIFS(EXAMES!E:E, EXAMES!D:D, H26, EXAMES!G:G, E26) -> 0 | BY26: =SUM(BN26:BU26)+SUM(BV26:BX26) -> 1379.4225 | CA26: BIANCA RODRIGUES DA SILVEIRA | CB26: =IF(SUM(BB26:BD26)+CF26<0, 0, SUM(BB26:BD26)+CF26) -> 0 | CC26: =IF(SUM(AV26:AW26)+CG26<0, 0, SUM(AV26:AW26)+CG26) -> 0 | CD26: =SUMIFS(ALIMENTAÇÃO!E:E, ALIMENTAÇÃO!D:D, H26, ALIMENTAÇÃO!G:G, E26) -> 560 | CE26: =SUMIFS(TRANSPORTE!E:E, TRANSPORTE!D:D, H26, TRANSPORTE!G:G, E26) -> 0 | CF26: =SUMIFS('PLANO DE SAÚDE'!E:E, 'PLANO DE SAÚDE'!D:D, H26, 'PLANO DE SAÚDE'!G:G, E26) -> 0 | CG26: =SUMIFS('PLANO ODONTO'!E:E, 'PLANO ODONTO'!D:D, H26, 'PLANO ODONTO'!G:G, E26) -> 14 | CH26: =BB26+BC26+BD26 -> 0 | CI26: =BI26+BJ26 -> 0 | CJ26: =AA26+AB26 -> 0 | CM26: =AV26+AW26 -> -14 | CN26: 1066.81 | CO26: -145.81 | CP26: 921 | CQ26: 1066.67 | CR26: 9.27 | CS26: 1066.67 | CT26: 85.33 | CU26: 459.47
A27: =IFERROR(__xludf.DUMMYFUNCTION("""COMPUTED_VALUE"""),"ANTONIO DIOGO DA SILVA TEIXEIRA") -> ANTONIO DIOGO DA SILVA TEIXEIRA | C27: =IF(COUNTIF(A:A, H27)>0, "OK", "Incompleto") -> OK | D27: =AN27+BY27 -> 3568.4689 | E27: 45809 | F27: 07.391.921/0001-71 | G27: 3416 | H27: BRUNA DE JESUS DA SILVA | I27: ASSISTENTE ADMINISTRAT | J27: 45292 | K27: 2000 | M27: 2000 | O27: 0 | P27: 0 | T27: 0 | Y27: 0 | AA27: 0 | AB27: 0 | AD27: 0 | AE27: 0 | AF27: 0 | AJ27: 0 | AM27: 0.34 | AN27: =SUM(M27:AM27) -> 2000.34 | AP27: 0 | AQ27: -120 | AT27: -0.1 | AV27: -14 | AY27: 0 | BB27: 0 | BC27: -2.01 | BF27: 0 | BG27: -157.23 | BH27: 0 | BI27: 0 | BL27: =SUM(AO27:BK27) -> -293.34 | BM27: =AN27+BL27 -> 1707 | BN27: =K27/12*1 -> 166.66667 | BO27: =K27/12*1 -> 166.66667 | BP27: =BO27/3 -> 55.555556 | BQ27: =CQ27*CR27% -> 157.23 | BR27: =CT27 -> 160 | BS27: =-(-CD27-AP27) -> 525 | BT27: =IF(CE27+AQ27<0, 0, CE27+AQ27) -> 204.9 | BU27: =CB27+CC27 -> 118.4 | BV27: =SUMIFS('SEGURO DE VIDA'!E:E, 'SEGURO DE VIDA'!D:D, H27, 'SEGURO DE VIDA'!G:G, E27) -> 13.71 | BW27: =SUMIFS(TREINAMENTOS!E:E, TREINAMENTOS!D:D, H27, TREINAMENTOS!G:G, E27) -> 0 | BX27: =SUMIFS(EXAMES!E:E, EXAMES!D:D, H27, EXAMES!G:G, E27) -> 0 | BY27: =SUM(BN27:BU27)+SUM(BV27:BX27) -> 1568.1289 | CA27: BRUNA DE JESUS DA SILVA | CB27: =IF(SUM(BB27:BD27)+CF27<0, 0, SUM(BB27:BD27)+CF27) -> 118.4 | CC27: =IF(SUM(AV27:AW27)+CG27<0, 0, SUM(AV27:AW27)+CG27) -> 0 | CD27: =SUMIFS(ALIMENTAÇÃO!E:E, ALIMENTAÇÃO!D:D, H27, ALIMENTAÇÃO!G:G, E27) -> 525 | CE27: =SUMIFS(TRANSPORTE!E:E, TRANSPORTE!D:D, H27, TRANSPORTE!G:G, E27) -> 324.9 | CF27: =SUMIFS('PLANO DE SAÚDE'!E:E, 'PLANO DE SAÚDE'!D:D, H27, 'PLANO DE SAÚDE'!G:G, E27) -> 120.41 | CG27: =SUMIFS('PLANO ODONTO'!E:E, 'PLANO ODONTO'!D:D, H27, 'PLANO ODONTO'!G:G, E27) -> 14 | CH27: =BB27+BC27+BD27 -> -2.01 | CI27: =BI27+BJ27 -> 0 | CJ27: =AA27+AB27 -> 0 | CM27: =AV27+AW27 -> -14 | CN27: 2000.34 | CO27: -293.34 | CP27: 1707 | CQ27: 2000 | CR27: 7.8615 | CS27: 2000 | CT27: 160 | CU27: 1392.8
A28: =IFERROR(__xludf.DUMMYFUNCTION("""COMPUTED_VALUE"""),"ARTHUR CASSILHAS DA MATA") -> ARTHUR CASSILHAS DA MATA | C28: =IF(COUNTIF(A:A, H28)>0, "OK", "Incompleto") -> OK | D28: =AN28+BY28 -> 1256.5867 | E28: 45809 | F28: 07.391.921/0001-71 | G28: 3550 | H28: BRUNNO MARQUES ESPOSITO | I28: AUX TEC TELECOMUNICAC | J28: 45831 | K28: 1518 | M28: 404.8 | O28: 0 | P28: 0 | T28: 0 | Y28: 0 | AA28: 0 | AB28: 0 | AD28: 0 | AE28: 0 | AF28: 0 | AJ28: 0 | AM28: 0.85 | AN28: =SUM(M28:AM28) -> 405.65 | AP28: 0 | AQ28: -24.29 | AT28: 0 | AV28: 0 | AY28: 0 | BB28: 0 | BC28: 0 | BF28: 0 | BG28: -30.36 | BH28: 0 | BI28: 0 | BL28: =SUM(AO28:BK28) -> -54.65 | BM28: =AN28+BL28 -> 351 | BN28: =K28/12*1 -> 126.5 | BO28: =K28/12*1 -> 126.5 | BP28: =BO28/3 -> 42.166667 | BQ28: =CQ28*CR28% -> 30.36 | BR28: =CT28 -> 32.38 | BS28: =-(-CD28-AP28) -> 210 | BT28: =IF(CE28+AQ28<0, 0, CE28+AQ28) -> 180.91 | BU28: =CB28+CC28 -> 0 | BV28: =SUMIFS('SEGURO DE VIDA'!E:E, 'SEGURO DE VIDA'!D:D, H28, 'SEGURO DE VIDA'!G:G, E28) -> 0 | BW28: =SUMIFS(TREINAMENTOS!E:E, TREINAMENTOS!D:D, H28, TREINAMENTOS!G:G, E28) -> 0 | BX28: =SUMIFS(EXAMES!E:E, EXAMES!D:D, H28, EXAMES!G:G, E28) -> 102.12 | BY28: =SUM(BN28:BU28)+SUM(BV28:BX28) -> 850.93667 | CA28: BRUNNO MARQUES ESPOSITO | CB28: =IF(SUM(BB28:BD28)+CF28<0, 0, SUM(BB28:BD28)+CF28) -> 0 | CC28: =IF(SUM(AV28:AW28)+CG28<0, 0, SUM(AV28:AW28)+CG28) -> 0 | CD28: =SUMIFS(ALIMENTAÇÃO!E:E, ALIMENTAÇÃO!D:D, H28, ALIMENTAÇÃO!G:G, E28) -> 210 | CE28: =SUMIFS(TRANSPORTE!E:E, TRANSPORTE!D:D, H28, TRANSPORTE!G:G, E28) -> 205.2 | CF28: =SUMIFS('PLANO DE SAÚDE'!E:E, 'PLANO DE SAÚDE'!D:D, H28, 'PLANO DE SAÚDE'!G:G, E28) -> 0 | CG28: =SUMIFS('PLANO ODONTO'!E:E, 'PLANO ODONTO'!D:D, H28, 'PLANO ODONTO'!G:G, E28) -> 0 | CH28: =BB28+BC28+BD28 -> 0 | CI28: =BI28+BJ28 -> 0 | CJ28: =AA28+AB28 -> 0 | CM28: =AV28+AW28 -> 0 | CN28: 405.65 | CO28: -54.65 | CP28: 351 | CQ28: 404.8 | CR28: 7.5 | CS28: 404.8 | CT28: 32.38 | CU28: 0
A29: =IFERROR(__xludf.DUMMYFUNCTION("""COMPUTED_VALUE"""),"ARTHUR RODRIGUES RANGEL") -> ARTHUR RODRIGUES RANGEL | C29: =IF(COUNTIF(A:A, H29)>0, "OK", "Incompleto") -> OK | D29: =AN29+BY29 -> 4368.7405 | E29: 45809 | F29: 07.391.921/0001-71 | G29: 288 | H29: CARLOS DA SILVA SANTOS | I29: INST REDES TELEMATICAS | J29: 44256 | K29: 2495.63 | M29: 2495.63 | O29: 0 | P29: 0 | T29: 0 | Y29: 0 | AA29: 0 | AB29: 0 | AD29: 0 | AE29: 0 | AF29: 0 | AJ29: 0 | AM29: 0.24 | AN29: =SUM(M29:AM29) -> 2495.87 | AP29: 0 | AQ29: -149.74 | AT29: -0.06 | AV29: 0 | AY29: 0 | BB29: 0 | BC29: -2.24 | BF29: 0 | BG29: -201.83 | BH29: 0 | BI29: 0 | BL29: =SUM(AO29:BK29) -> -353.87 | BM29: =AN29+BL29 -> 2142 | BN29: =K29/12*1 -> 207.96917 | BO29: =K29/12*1 -> 207.96917 | BP29: =BO29/3 -> 69.323056 | BQ29: =CQ29*CR29% -> 201.82908 | BR29: =CT29 -> 199.65 | BS29: =-(-CD29-AP29) -> 665 | BT29: =IF(CE29+AQ29<0, 0, CE29+AQ29) -> 175.16 | BU29: =CB29+CC29 -> 132.26 | BV29: =SUMIFS('SEGURO DE VIDA'!E:E, 'SEGURO DE VIDA'!D:D, H29, 'SEGURO DE VIDA'!G:G, E29) -> 13.71 | BW29: =SUMIFS(TREINAMENTOS!E:E, TREINAMENTOS!D:D, H29, TREINAMENTOS!G:G, E29) -> 0 | BX29: =SUMIFS(EXAMES!E:E, EXAMES!D:D, H29, EXAMES!G:G, E29) -> 0 | BY29: =SUM(BN29:BU29)+SUM(BV29:BX29) -> 1872.8705 | CA29: CARLOS DA SILVA SANTOS | CB29: =IF(SUM(BB29:BD29)+CF29<0, 0, SUM(BB29:BD29)+CF29) -> 132.26 | CC29: =IF(SUM(AV29:AW29)+CG29<0, 0, SUM(AV29:AW29)+CG29) -> 0 | CD29: =SUMIFS(ALIMENTAÇÃO!E:E, ALIMENTAÇÃO!D:D, H29, ALIMENTAÇÃO!G:G, E29) -> 665 | CE29: =SUMIFS(TRANSPORTE!E:E, TRANSPORTE!D:D, H29, TRANSPORTE!G:G, E29) -> 324.9 | CF29: =SUMIFS('PLANO DE SAÚDE'!E:E, 'PLANO DE SAÚDE'!D:D, H29, 'PLANO DE SAÚDE'!G:G, E29) -> 134.5 | CG29: =SUMIFS('PLANO ODONTO'!E:E, 'PLANO ODONTO'!D:D, H29, 'PLANO ODONTO'!G:G, E29) -> 0 | CH29: =BB29+BC29+BD29 -> -2.24 | CI29: =BI29+BJ29 -> 0 | CJ29: =AA29+AB29 -> 0 | CM29: =AV29+AW29 -> 0 | CN29: 2495.87 | CO29: -353.87 | CP29: 2142 | CQ29: 2495.63 | CR29: 8.0873 | CS29: 2495.63 | CT29: 199.65 | CU29: 1888.43
A30: =IFERROR(__xludf.DUMMYFUNCTION("""COMPUTED_VALUE"""),"ARTHUR SOUZA LEMOS PINHEIRO") -> ARTHUR SOUZA LEMOS PINHEIRO | C30: =IF(COUNTIF(A:A, H30)>0, "OK", "Incompleto") -> OK | D30: =AN30+BY30 -> 3519.45 | E30: 45809 | F30: 07.391.921/0001-71 | G30: 3493 | H30: CARLOS EDUARDO DE MORAIS RODRIGUES JUNIOR | I30: INSTALADOR | J30: 45635 | K30: 1800 | M30: 1800 | O30: 0 | P30: 0 | T30: 0 | Y30: 0 | AA30: 0 | AB30: 0 | AD30: 0 | AE30: 0 | AF30: 0 | AJ30: 0 | AM30: 0.51 | AN30: =SUM(M30:AM30) -> 1800.51 | AP30: 0 | AQ30: -108 | AT30: -0.28 | AV30: -14 | AY30: 0 | BB30: 0 | BC30: 0 | BF30: 0 | BG30: -139.23 | BH30: 0 | BI30: 0 | BL30: =SUM(AO30:BK30) -> -261.51 | BM30: =AN30+BL30 -> 1539 | BN30: =K30/12*1 -> 150 | BO30: =K30/12*1 -> 150 | BP30: =BO30/3 -> 50 | BQ30: =CQ30*CR30% -> 139.23 | BR30: =CT30 -> 144 | BS30: =-(-CD30-AP30) -> 595 | BT30: =IF(CE30+AQ30<0, 0, CE30+AQ30) -> 216.9 | BU30: =CB30+CC30 -> 0 | BV30: =SUMIFS('SEGURO DE VIDA'!E:E, 'SEGURO DE VIDA'!D:D, H30, 'SEGURO DE VIDA'!G:G, E30) -> 13.71 | BW30: =SUMIFS(TREINAMENTOS!E:E, TREINAMENTOS!D:D, H30, TREINAMENTOS!G:G, E30) -> 260.1 | BX30: =SUMIFS(EXAMES!E:E, EXAMES!D:D, H30, EXAMES!G:G, E30) -> 0 | BY30: =SUM(BN30:BU30)+SUM(BV30:BX30) -> 1718.94 | CA30: CARLOS EDUARDO DE MORAIS ROL | CB30: =IF(SUM(BB30:BD30)+CF30<0, 0, SUM(BB30:BD30)+CF30) -> 0 | CC30: =IF(SUM(AV30:AW30)+CG30<0, 0, SUM(AV30:AW30)+CG30) -> 0 | CD30: =SUMIFS(ALIMENTAÇÃO!E:E, ALIMENTAÇÃO!D:D, H30, ALIMENTAÇÃO!G:G, E30) -> 595 | CE30: =SUMIFS(TRANSPORTE!E:E, TRANSPORTE!D:D, H30, TRANSPORTE!G:G, E30) -> 324.9 | CF30: =SUMIFS('PLANO DE SAÚDE'!E:E, 'PLANO DE SAÚDE'!D:D, H30, 'PLANO DE SAÚDE'!G:G, E30) -> 0 | CG30: =SUMIFS('PLANO ODONTO'!E:E, 'PLANO ODONTO'!D:D, H30, 'PLANO ODONTO'!G:G, E30) -> 14 | CH30: =BB30+BC30+BD30 -> 0 | CI30: =BI30+BJ30 -> 0 | CJ30: =AA30+AB30 -> 0 | CM30: =AV30+AW30 -> -14 | CN30: 1800.51 | CO30: -261.51 | CP30: 1539 | CQ30: 1800 | CR30: 7.735 | CS30: 1800 | CT30: 144 | CU30: 1192.8
A31: =IFERROR(__xludf.DUMMYFUNCTION("""COMPUTED_VALUE"""),"ARTHUR TELES SILVA DE ANDRADE") -> ARTHUR TELES SILVA DE ANDRADE | C31: =IF(COUNTIF(A:A, H31)>0, "OK", "Incompleto") -> OK | D31: =AN31+BY31 -> 3048.227 | E31: 45809 | F31: 07.391.921/0001-71 | G31: 182 | H31: CARLOS EDUARDO SILVA DE SOUZA | I31: COORDENADOR DE TELEC | J31: 42248 | K31: 4336.05 | L31: Férias | M31: 1445.35 | O31: 0 | P31: 0 | T31: 0 | Y31: 0 | AA31: 0 | AB31: 0 | AD31: 0 | AE31: 0 | AF31: 0 | AJ31: 0 | AM31: 0.63 | AN31: =SUM(M31:AM31) -> 1445.98 | AP31: 0 | AQ31: 0 | AT31: -0.85 | AV31: -14 | AY31: 0 | BB31: -65.27 | BC31: -2.24 | BF31: 0 | BG31: -195.62 | BH31: 0 | BI31: 0 | BL31: =SUM(AO31:BK31) -> -277.98 | BM31: =AN31+BL31 -> 1168 | BN31: =K31/12*1 -> 361.3375 | BO31: =K31/12*1 -> 361.3375 | BP31: =BO31/3 -> 120.44583 | BQ31: =CQ31*CR31% -> 150.41613 | BR31: =CT31 -> 115.62 | BS31: =-(-CD31-AP31) -> 245 | BT31: =IF(CE31+AQ31<0, 0, CE31+AQ31) -> 0 | BU31: =CB31+CC31 -> 132.26 | BV31: =SUMIFS('SEGURO DE VIDA'!E:E, 'SEGURO DE VIDA'!D:D, H31, 'SEGURO DE VIDA'!G:G, E31) -> 13.71 | BW31: =SUMIFS(TREINAMENTOS!E:E, TREINAMENTOS!D:D, H31, TREINAMENTOS!G:G, E31) -> 0 | BX31: =SUMIFS(EXAMES!E:E, EXAMES!D:D, H31, EXAMES!G:G, E31) -> 102.12 | BY31: =SUM(BN31:BU31)+SUM(BV31:BX31) -> 1602.247 | CA31: CARLOS EDUARDO SILVA DE SOUZ | CB31: =IF(SUM(BB31:BD31)+CF31<0, 0, SUM(BB31:BD31)+CF31) -> 132.26 | CC31: =IF(SUM(AV31:AW31)+CG31<0, 0, SUM(AV31:AW31)+CG31) -> 0 | CD31: =SUMIFS(ALIMENTAÇÃO!E:E, ALIMENTAÇÃO!D:D, H31, ALIMENTAÇÃO!G:G, E31) -> 245 | CE31: =SUMIFS(TRANSPORTE!E:E, TRANSPORTE!D:D, H31, TRANSPORTE!G:G, E31) -> 0 | CF31: =SUMIFS('PLANO DE SAÚDE'!E:E, 'PLANO DE SAÚDE'!D:D, H31, 'PLANO DE SAÚDE'!G:G, E31) -> 199.77 | CG31: =SUMIFS('PLANO ODONTO'!E:E, 'PLANO ODONTO'!D:D, H31, 'PLANO ODONTO'!G:G, E31) -> 14 | CH31: =BB31+BC31+BD31 -> -67.51 | CI31: =BI31+BJ31 -> 0 | CJ31: =AA31+AB31 -> 0 | CM31: =AV31+AW31 -> -14 | CN31: 1445.98 | CO31: -277.98 | CP31: 1168 | CQ31: 1445.35 | CR31: 10.4069 | CS31: 1445.35 | CT31: 115.62 | CU31: 838.15
